Workbook

Sheet 材料价格
A1: 材料清单报价单 | E1: 成本汇总 | K1: 3#
A2: 材料 | B2: 单价 | C2: 备注 | E2: 序号 | F2: 窗型 | G2: 面积 | H2: 成本单价 | I2: 成本合价 | K2: ='3#楼工程量统计'!N4 -> 序号 | L2: ='3#楼工程量统计'!O4 -> 窗型 | M2: ='3#楼工程量统计'!P4 -> 面积 | N2: ='3#楼工程量统计'!Q4 -> 成本单价 | O2: ='3#楼工程量统计'!R4 -> 成本合价
A3: 40*20*2.0钢副框 | B3: 7.5 | E3: 1 | F3: 65F铝合金门 | G3: =M3+M14+M25+M36+M47 -> 5489.078 | H3: =I3/G3 -> 1497.9923 | I3: =O3+O14+O25+O36+O47 -> 8222596.5 | J3: =H3+20 -> 1517.9923 | K3: ='3#楼工程量统计'!N5 -> 1 | L3: ='3#楼工程量统计'!O5 -> 65F铝合金门 | M3: ='3#楼工程量统计'!P5 -> 1719.353 | N3: ='3#楼工程量统计'!Q5 -> 1627.2159 | O3: ='3#楼工程量统计'!R5 -> 2797758.6
A4: 铝锭价格 | B4: =21030*1.05 -> 22081.5 | C4: 2025.10.24 | E4: 2 | F4: 65F铝合金窗 | G4: =M4+M15+M26+M37+M48 -> 5125.196 | H4: =I4/G4 -> 1475.3155 | I4: =O4+O15+O26+O37+O48 -> 7561281.3 | J4: =H4+20 -> 1495.3155 | K4: ='3#楼工程量统计'!N6 -> 2 | L4: ='3#楼工程量统计'!O6 -> 65F铝合金窗 | M4: ='3#楼工程量统计'!P6 -> 2933.396 | N4: ='3#楼工程量统计'!Q6 -> 1427.8592 | O4: ='3#楼工程量统计'!R6 -> 4188476.5
A5: 26mm II/IC | B5: 24000 | C5: 氟碳三涂·进口条 | E5: 3 | F5: 125铝合金幕墙 | G5: =M5+M16+M27+M38+M49 -> 791.39 | H5: =I5/G5 -> 1362.8416 | I5: =O5+O16+O27+O38+O49 -> 1078539.3 | J5: =H5+20 -> 1382.8416 | K5: ='3#楼工程量统计'!N7 -> 3 | L5: ='3#楼工程量统计'!O7 -> 125铝合金幕墙 | M5: ='3#楼工程量统计'!P7 -> 111.48 | N5: ='3#楼工程量统计'!Q7 -> 1855.04 | O5: ='3#楼工程量统计'!R7 -> 206799.86
A6: 普铝加工费 | B6: 17700 | C6: 1.8mm壁厚 | E6: 4 | F6: 铝合金百叶窗 | G6: =M6+M17+M28+M39+M50 -> 1121.338 | H6: =I6/G6 -> 971.62762 | I6: =O6+O17+O28+O39+O50 -> 1089523 | J6: =H6+20 -> 991.62762 | K6: ='3#楼工程量统计'!N8 -> 4 | L6: ='3#楼工程量统计'!O8 -> 铝合金百叶窗 | M6: ='3#楼工程量统计'!P8 -> 114.528 | N6: ='3#楼工程量统计'!Q8 -> 794 | O6: ='3#楼工程量统计'!R8 -> 90935.232
A7: 幕墙加工费 | B7: 19200 | E7: 5 | F7: 通透格栅 | G7: =M7+M18+M29+M40+M51 -> 174.42 | H7: =I7/G7 -> 1117.43 | I7: =O7+O18+O29+O40+O51 -> 194902.14 | J7: =H7+20 -> 1137.43 | K7: ='3#楼工程量统计'!N9 -> 5 | L7: ='3#楼工程量统计'!O9 -> 通透格栅 | M7: ='3#楼工程量统计'!P9 -> 0 | N7: ='3#楼工程量统计'!Q9 -> 0 | O7: ='3#楼工程量统计'!R9 -> 0
A8: 百叶加工费 | B8: 73 | E8: 6 | F8: 防蚊隐形纱窗 | G8: =M8+M19+M30+M41+M52 -> 1238.2944 | H8: 133 | I8: =O8+O19+O30+O41+O52 -> 0 | K8: ='3#楼工程量统计'!N10 -> 6 | L8: ='3#楼工程量统计'!O10 -> 防蚊纱窗 | M8: ='3#楼工程量统计'!P10 -> 702.1864 | N8: ='3#楼工程量统计'!Q10 -> 0 | O8: ='3#楼工程量统计'!R10 -> 0
A9: 白料加工费 | B9: 2900 | E9: 7 | F9: 阳台铝合金栏杆m | G9: =M9+M20+M31+M42+M53 -> 1765.5 | H9: 550 | I9: =O9+O20+O31+O42+O53 -> 0 | J9: =H9+20 -> 570 | K9: ='3#楼工程量统计'!N11 -> 7 | L9: ='3#楼工程量统计'!O11 -> 阳台铝合金栏杆m | M9: ='3#楼工程量统计'!P11 -> 128.4 | N9: ='3#楼工程量统计'!Q11 -> 0 | O9: ='3#楼工程量统计'!R11 -> 0
A10: 6单银Low-E+12A+6 | B10: =48+65+35 -> 148 | E10: 8 | F10: 穿孔铝单板 | G10: =M10+M21+M32+M43+M54 -> 345 | H10: 600 | I10: =O10+O21+O32+O43+O54 -> 0 | J10: =H10+20 -> 620 | K10: ='3#楼工程量统计'!N12 -> 8 | L10: ='3#楼工程量统计'!O12 -> 穿孔铝单板 | M10: ='3#楼工程量统计'!P12 -> 0 | N10: ='3#楼工程量统计'!Q12 -> 0 | O10: ='3#楼工程量统计'!R12 -> 0
A11: 8单银Low-E+12Ar+8+12A+8mm | B11: 312 | C11: 均质处理 | E11: 9 | G11: =SUM(G3:G10) -> 16050.216 | H11: =I11/G11 -> 1130.6291 | I11: =SUM(I3:I10) -> 18146842 | K11: ='3#楼工程量统计'!N13 -> 9 | L11: ='3#楼工程量统计'!O13 -> 0 | M11: ='3#楼工程量统计'!P13 -> 4878.757 | N11: ='3#楼工程量统计'!Q13 -> 1492.9971 | O11: ='3#楼工程量统计'!R13 -> 7283970.2
A12: 10单银Low-E+12Ar+10+12A+10mm | B12: 395 | C12: 超白 海阳顺达 | K12: 4#
A13: 12单银Low-E+12Ar+12+12A+12mm | B13: 470 | C13: 超白 海阳顺达 | K13: ='4#楼工程量统计'!N3 -> 序号 | L13: ='4#楼工程量统计'!O3 -> 窗型 | M13: ='4#楼工程量统计'!P3 -> 面积 | N13: ='4#楼工程量统计'!Q3 -> 成本单价 | O13: ='4#楼工程量统计'!R3 -> 成本合价
A14: 内开内倒窗（隐藏式） | B14: =145+8 -> 153 | C14: 坚朗(打logo) | K14: ='4#楼工程量统计'!N4 -> 1 | L14: ='4#楼工程量统计'!O4 -> 65F铝合金门 | M14: ='4#楼工程量统计'!P4 -> 107.78 | N14: ='4#楼工程量统计'!Q4 -> 1184.9823 | O14: ='4#楼工程量统计'!R4 -> 127717.39
A15: 内平开窗（隐藏式） | B15: =72+8 -> 80 | C15: 坚朗 | K15: ='4#楼工程量统计'!N5 -> 2 | L15: ='4#楼工程量统计'!O5 -> 65F铝合金窗 | M15: ='4#楼工程量统计'!P5 -> 644.52 | N15: ='4#楼工程量统计'!Q5 -> 1537.8533 | O15: ='4#楼工程量统计'!R5 -> 991177.19
A16: 外平开窗 | B16: =80+8 -> 88 | C16: 坚朗 | K16: ='4#楼工程量统计'!N6 -> 3 | L16: ='4#楼工程量统计'!O6 -> 125铝合金幕墙 | M16: ='4#楼工程量统计'!P6 -> 0 | N16: ='4#楼工程量统计'!Q6 -> 0 | O16: ='4#楼工程量统计'!R6 -> 0
A17: 外悬窗 | B17: =107+8 -> 115 | C17: 坚朗 | K17: ='4#楼工程量统计'!N7 -> 4 | L17: ='4#楼工程量统计'!O7 -> 铝合金百叶窗 | M17: ='4#楼工程量统计'!P7 -> 18.38 | N17: ='4#楼工程量统计'!Q7 -> 964 | O17: ='4#楼工程量统计'!R7 -> 17718.32
A18: 平开电动开窗器(安装） | B18: =1150+200 -> 1350 | C18: 坚朗 | K18: ='4#楼工程量统计'!N8 -> 5 | L18: ='4#楼工程量统计'!O8 -> 通透格栅 | M18: ='4#楼工程量统计'!P8 -> 0 | N18: ='4#楼工程量统计'!Q8 -> 0 | O18: ='4#楼工程量统计'!R8 -> 0
A19: 单开门 | B19: 230 | C19: 坚朗 | K19: ='4#楼工程量统计'!N9 -> 6 | L19: ='4#楼工程量统计'!O9 -> 防蚊纱窗 | M19: ='4#楼工程量统计'!P9 -> 123.818 | N19: ='4#楼工程量统计'!Q9 -> 0 | O19: ='4#楼工程量统计'!R9 -> 0
A20: 对开门 | B20: 335 | C20: 坚朗 | K20: ='4#楼工程量统计'!N10 -> 7 | L20: ='4#楼工程量统计'!O10 -> 阳台铝合金栏杆m | M20: ='4#楼工程量统计'!P10 -> 0 | N20: ='4#楼工程量统计'!Q10 -> 0 | O20: ='4#楼工程量统计'!R10 -> 0
K21: ='4#楼工程量统计'!N11 -> 8 | L21: ='4#楼工程量统计'!O11 -> 穿孔铝单板 | M21: ='4#楼工程量统计'!P11 -> 0 | N21: ='4#楼工程量统计'!Q11 -> 0 | O21: ='4#楼工程量统计'!R11 -> 0
K22: ='4#楼工程量统计'!N12 -> 9 | L22: ='4#楼工程量统计'!O12 -> 0 | M22: ='4#楼工程量统计'!P12 -> 770.68 | N22: ='4#楼工程量统计'!Q12 -> 1474.8182 | O22: ='4#楼工程量统计'!R12 -> 1136612.9
A23: 通透格栅 | B23: 700 | K23: 5#
A24: 中性硅酮密封胶（500ml)耐火胶 | B24: =23.6/500*300 -> 14.16 | C24: 安泰 | K24: ='5#楼工程量统计'!M4 -> 序号 | L24: ='5#楼工程量统计'!N4 -> 窗型 | M24: ='5#楼工程量统计'!O4 -> 面积 | N24: ='5#楼工程量统计'!P4 -> 成本单价 | O24: ='5#楼工程量统计'!Q4 -> 成本合价
A25: 中性硅酮密封胶（500ml) | B25: =14.2/500*300 -> 8.52 | C25: 安泰 | K25: ='5#楼工程量统计'!M5 -> 1 | L25: ='5#楼工程量统计'!N5 -> 65F铝合金门 | M25: ='5#楼工程量统计'!O5 -> 1236.605 | N25: ='5#楼工程量统计'!P5 -> 1406.672 | O25: ='5#楼工程量统计'!Q5 -> 1739497.6
A26: 发泡胶 | B26: 23 | C26: 固诺 | K26: ='5#楼工程量统计'!M6 -> 2 | L26: ='5#楼工程量统计'!N6 -> 65F铝合金窗 | M26: ='5#楼工程量统计'!O6 -> 174.03 | N26: ='5#楼工程量统计'!P6 -> 1589.7681 | O26: ='5#楼工程量统计'!Q6 -> 276667.34
A27: 内平开金刚纱窗 | K27: ='5#楼工程量统计'!M7 -> 3 | L27: ='5#楼工程量统计'!N7 -> 125铝合金幕墙 | M27: ='5#楼工程量统计'!O7 -> 211.68 | N27: ='5#楼工程量统计'!P7 -> 1118.645 | O27: ='5#楼工程量统计'!Q7 -> 236794.77
A28: 隐形纱窗 | B28: 118 | K28: ='5#楼工程量统计'!M8 -> 4 | L28: ='5#楼工程量统计'!N8 -> 铝合金百叶窗 | M28: ='5#楼工程量统计'!O8 -> 329.84 | N28: ='5#楼工程量统计'!P8 -> 1004 | O28: ='5#楼工程量统计'!Q8 -> 331159.36
K29: ='5#楼工程量统计'!M9 -> 5 | L29: ='5#楼工程量统计'!N9 -> 通透格栅 | M29: ='5#楼工程量统计'!O9 -> 0 | N29: ='5#楼工程量统计'!P9 -> 0 | O29: ='5#楼工程量统计'!Q9 -> 0
K30: ='5#楼工程量统计'!M10 -> 6 | L30: ='5#楼工程量统计'!N10 -> 防蚊纱窗 | M30: ='5#楼工程量统计'!O10 -> 121.6 | N30: ='5#楼工程量统计'!P10 -> 0 | O30: ='5#楼工程量统计'!Q10 -> 0
K31: ='5#楼工程量统计'!M11 -> 7 | L31: ='5#楼工程量统计'!N11 -> 阳台铝合金栏杆m | M31: ='5#楼工程量统计'!O11 -> 483.3 | N31: ='5#楼工程量统计'!P11 -> 0 | O31: ='5#楼工程量统计'!Q11 -> 0
K32: ='5#楼工程量统计'!M12 -> 8 | L32: ='5#楼工程量统计'!N12 -> 穿孔铝单板 | M32: ='5#楼工程量统计'!O12 -> 135 | N32: ='5#楼工程量统计'!P12 -> 0 | O32: ='5#楼工程量统计'!Q12 -> 0
K33: ='5#楼工程量统计'!M13 -> 9 | L33: ='5#楼工程量统计'!N13 -> 0 | M33: ='5#楼工程量统计'!O13 -> 1952.155 | N33: ='5#楼工程量统计'!P13 -> 1323.7264 | O33: ='5#楼工程量统计'!Q13 -> 2584119.1
K34: 6#
K35: ='6#楼工程量统计 '!M4 -> 序号 | L35: ='6#楼工程量统计 '!N4 -> 窗型 | M35: ='6#楼工程量统计 '!O4 -> 面积 | N35: ='6#楼工程量统计 '!P4 -> 成本单价 | O35: ='6#楼工程量统计 '!Q4 -> 成本合价
K36: ='6#楼工程量统计 '!M5 -> 1 | L36: ='6#楼工程量统计 '!N5 -> 65F铝合金门 | M36: ='6#楼工程量统计 '!O5 -> 2384.43 | N36: ='6#楼工程量统计 '!P5 -> 1463.4744 | O36: ='6#楼工程量统计 '!Q5 -> 3489552.3
K37: ='6#楼工程量统计 '!M6 -> 2 | L37: ='6#楼工程量统计 '!N6 -> 65F铝合金窗 | M37: ='6#楼工程量统计 '!O6 -> 393.89 | N37: ='6#楼工程量统计 '!P6 -> 1594.5882 | O37: ='6#楼工程量统计 '!Q6 -> 628092.36
K38: ='6#楼工程量统计 '!M7 -> 3 | L38: ='6#楼工程量统计 '!N7 -> 125铝合金幕墙 | M38: ='6#楼工程量统计 '!O7 -> 277.83 | N38: ='6#楼工程量统计 '!P7 -> 1105.1281 | O38: ='6#楼工程量统计 '!Q7 -> 307037.74
K39: ='6#楼工程量统计 '!M8 -> 4 | L39: ='6#楼工程量统计 '!N8 -> 铝合金百叶窗 | M39: ='6#楼工程量统计 '!O8 -> 603.76 | N39: ='6#楼工程量统计 '!P8 -> 1004 | O39: ='6#楼工程量统计 '!Q8 -> 606175.04
K40: ='6#楼工程量统计 '!M9 -> 5 | L40: ='6#楼工程量统计 '!N9 -> 通透格栅 | M40: ='6#楼工程量统计 '!O9 -> 0 | N40: ='6#楼工程量统计 '!P9 -> 0 | O40: ='6#楼工程量统计 '!Q9 -> 0
...

Sheet 汇总表
A1: 成本汇总表
A2: 序号 | B2: 楼号 | C2: 数量 | D2: 面积 | E2: 成本单价 | F2: 成本合价 | G2: 备注
A3: 1 | B3: 3# | C3: ='3#楼工程量统计'!F70 -> 967 | D3: ='3#楼工程量统计'!H70 -> 4878.757
A4: 2 | B4: 4# | C4: ='4#楼工程量统计'!F24 -> 153 | D4: ='4#楼工程量统计'!H24 -> 770.68
A5: 3 | B5: 5# | C5: ='5#楼工程量统计'!F36 -> 550 | D5: ='5#楼工程量统计'!H36 -> 1952.155
A6: 4 | B6: 6# | C6: ='6#楼工程量统计 '!F33 -> 1038 | D6: ='6#楼工程量统计 '!H33 -> 3659.91
A7: 5 | B7: 8# | C7: ='8#楼工程量统计'!F40 -> 286 | D7: ='8#楼工程量统计'!H40 -> 1439.92
A8: 6 | C8: =SUM(C3:C7) -> 2994 | D8: =SUM(D3:D7) -> 12701.422
D10: =D8/C8 -> 4.2422919

Sheet 3#楼工程量统计
A1: 3#工程量统计
A2: 序号 | B2: 类型 | C2: 设计编号 | D2: 洞口宽(mm) | E2: 洞口高(mm) | F2: 数量 | G2: 单樘面积(㎡) | H2: 工程量(㎡) | I2: 成本单价 | K2: 成本合价 | L2: 备注 | M2: 断桥铝合金(6LOW-E+12A+6)
A3: 1 | B3: 外门 | C3: WM1121 | D3: 1100 | E3: 2050 | F3: 1 | G3: 2.125 | H3: =F3*G3 -> 2.125 | I3: ='WM1127'!B371 -> 1663.91 | K3: =I3*H3 -> 3535.8088
A4: 2 | C4: WM1127 | D4: 1100 | E4: 2650 | F4: 288 | G4: 2.785 | H4: =F4*G4 -> 802.08 | I4: ='WM1127'!B371 -> 1663.91 | K4: =I4*H4 -> 1334588.9 | N4: 序号 | O4: 窗型 | P4: 面积 | Q4: 成本单价 | R4: 成本合价
A5: 3 | C5: WM1635 | D5: 1600 | E5: 3500 | F5: 6 | G5: 5.325 | H5: =F5*G5 -> 31.95 | I5: ='WM1127'!B371 -> 1663.91 | K5: =I5*H5 -> 53161.925 | N5: 1 | O5: 65F铝合金门 | P5: =SUM(H3:H20,H47:H52)-P7 -> 1719.353 | Q5: =R5/P5 -> 1627.2159 | R5: =SUM(K3:K20,K47:K52)-R7 -> 2797758.6
A6: 4 | C6: WM1822 | D6: 1800 | E6: 2150 | F6: 4 | G6: 3.52 | H6: =F6*G6 -> 14.08 | I6: ='WM1127'!B371 -> 1663.91 | K6: =I6*H6 -> 23427.853 | N6: 2 | O6: 65F铝合金窗 | P6: =SUM(H21:H46) -> 2933.396 | Q6: =R6/P6 -> 1427.8592 | R6: =SUM(K21:K46) -> 4188476.5
A7: 5 | C7: WM1830 | D7: 1800 | E7: 3000 | F7: 4 | G7: 5.05 | H7: =F7*G7 -> 20.2 | I7: ='WM1127'!B371 -> 1663.91 | K7: =I7*H7 -> 33610.982 | N7: 3 | O7: 125铝合金幕墙 | P7: =H13+H19 -> 111.48 | Q7: =R7/P7 -> 1855.04 | R7: =K13+K19 -> 206799.86
A8: 6 | C8: WM2021 | D8: 2000 | E8: 2150 | F8: 4 | G8: =2.125*2 -> 4.25 | H8: =F8*G8 -> 17 | I8: ='WM1127'!B371 -> 1663.91 | K8: =I8*H8 -> 28286.47 | N8: 4 | O8: 铝合金百叶窗 | P8: =SUM(H53:H67) -> 114.528 | Q8: =R8/P8 -> 794 | R8: =SUM(K53:K67) -> 90935.232
A9: 7 | C9: WM2035 | D9: 2000 | E9: 3500 | F9: 2 | G9: 6.57 | H9: =F9*G9 -> 13.14 | I9: ='WM1127'!B371 -> 1663.91 | K9: =I9*H9 -> 21863.777 | N9: 5 | O9: 通透格栅
A10: 8 | C10: WM2335 | D10: 2300 | E10: 3500 | F10: 4 | G10: 7.48 | H10: =F10*G10 -> 29.92 | I10: ='WM1127'!B371 -> 1663.91 | K10: =I10*H10 -> 49784.187 | N10: 6 | O10: 防蚊纱窗 | P10: =SUM(H68) -> 702.1864
A11: 9 | C11: WM2338 | D11: 2300 | E11: 3800 | F11: 2 | G11: 8.178 | H11: =F11*G11 -> 16.356 | I11: ='WM1127'!B371 -> 1663.91 | K11: =I11*H11 -> 27214.912 | N11: 7 | O11: 阳台铝合金栏杆m | P11: =SUM(H69) -> 128.4
A12: 10 | C12: WM2338-G | D12: 2300 | E12: 3800 | F12: 6 | G12: 8.17 | H12: =F12*G12 -> 49.02 | I12: ='WM1127'!B371 -> 1663.91 | K12: =I12*H12 -> 81564.868 | L12: 上拱窗户优化为固玻，无需开启 | N12: 8 | O12: 穿孔铝单板
A13: 11 | C13: WM2480-G | D13: 2400 | E13: 8000 | F13: 4 | G13: 18.58 | H13: =F13*G13 -> 74.32 | I13: ='WM2480'!G126 -> 1855.04 | K13: =I13*H13 -> 137866.57 | L13: 上拱窗户优化为固玻，无需开启 | M13: 125幕墙 | N13: 9 | P13: =SUM(P5:P9) -> 4878.757 | Q13: =R13/P13 -> 1492.9971 | R13: =SUM(R5:R8) -> 7283970.2
A14: 12 | C14: WM3935 | D14: 3900 | E14: 3500 | F14: 2 | G14: =6.417*2 -> 12.834 | H14: =F14*G14 -> 25.668 | I14: ='WM1127'!B371 -> 1663.91 | K14: =I14*H14 -> 42709.242
A15: 13 | C15: WM5424 | D15: 5400 | E15: 2400 | F15: 4 | G15: =5.4*2.4 -> 12.96 | H15: =F15*G15 -> 51.84 | I15: ='WM1127'!B371 -> 1663.91 | K15: =I15*H15 -> 86257.094
A16: 14 | C16: WM1126-xf | D16: 1100 | E16: 2550 | F16: 2 | G16: 2.675 | H16: =F16*G16 -> 5.35 | I16: ='WM1127'!B371 -> 1663.91 | K16: =I16*H16 -> 8901.9185 | L16: 消防救援口
A17: 15 | C17: WM1127-xf | D17: 1100 | E17: 2650 | F17: 4 | G17: 2.785 | H17: =F17*G17 -> 11.14 | I17: ='WM1127'!B371 -> 1663.91 | K17: =I17*H17 -> 18535.957 | L17: 消防救援口
A18: 16 | C18: WM2035-xf | D18: 2000 | E18: 3500 | F18: 4 | G18: 6.57 | H18: =F18*G18 -> 26.28 | I18: ='WM1127'!B371 -> 1663.91 | K18: =I18*H18 -> 43727.555 | L18: 消防救援口
A19: 17 | C19: WM2480-G-xf | D19: 2400 | E19: 8000 | F19: 2 | G19: 18.58 | H19: =F19*G19 -> 37.16 | I19: ='WM2480'!G126 -> 1855.04 | K19: =I19*H19 -> 68933.286 | L19: 消防救援口，上拱窗户优化为固玻，无需开启 | M19: 125幕墙
A20: 18 | C20: WM3935-xf | D20: 3900 | E20: 3500 | F20: 2 | G20: =6.417*2 -> 12.834 | H20: =F20*G20 -> 25.668 | I20: ='WM1127'!B371 -> 1663.91 | K20: =I20*H20 -> 42709.242 | L20: 消防救援口
A21: 19 | B21: 外窗 | C21: C1014 | D21: 1000 | E21: 1400 | F21: 30 | G21: 1.1 | H21: =F21*G21 -> 33 | I21: ='C1014'!B371 -> 2372.44 | K21: =I21*H21 -> 78290.52
A22: 20 | C22: C1117 | D22: 1100 | E22: 1700 | F22: 22 | G22: 1.74 | H22: =F22*G22 -> 38.28 | I22: ='C1117'!B371 -> 1875.61 | K22: =I22*H22 -> 71798.351
A23: 21 | C23: C1121 | D23: 1100 | E23: 2050 | F23: 12 | G23: 2.125 | H23: =F23*G23 -> 25.5 | I23: ='C1122'!B371 -> 1792.83 | K23: =I23*H23 -> 45717.165
A24: 22 | C24: C1122 | D24: 1100 | E24: 2150 | F24: 8 | G24: 2.125 | H24: =F24*G24 -> 17 | I24: ='C1122'!B371 -> 1792.83 | K24: =I24*H24 -> 30478.11
A25: 23 | C25: C1126 | D25: 1100 | E25: 2550 | F25: 14 | G25: 2.675 | H25: =F25*G25 -> 37.45 | I25: ='C1122'!B371 -> 1792.83 | K25: =I25*H25 -> 67141.483
A26: 24 | C26: C1127 | D26: 1100 | E26: 2650 | F26: 56 | G26: 2.785 | H26: =F26*G26 -> 155.96 | I26: ='C1122'!B371 -> 1792.83 | K26: =I26*H26 -> 279609.77
A27: 25 | C27: C1417 | D27: 1400 | E27: 1700 | F27: 30 | G27: 1.87 | H27: =F27*G27 -> 56.1 | I27: ='C1417'!B371 -> 1810.03 | K27: =I27*H27 -> 101542.68
A28: 26 | C28: C1837 | D28: 1800 | E28: 3700 | F28: 4 | G28: 6.31 | H28: =F28*G28 -> 25.24 | I28: ='C2430'!B371 -> 1459.77 | K28: =I28*H28 -> 36844.595
A29: 27 | C29: C2330 | D29: 2300 | E29: 3000 | F29: 32 | G29: 6.33 | H29: =F29*G29 -> 202.56 | I29: ='C2430'!B371 -> 1459.77 | K29: =I29*H29 -> 295691.01
A30: 28 | C30: C2335 | D30: 2300 | E30: 3500 | F30: 6 | G30: 7.48 | H30: =F30*G30 -> 44.88 | I30: ='C2430'!B371 -> 1459.77 | K30: =I30*H30 -> 65514.478
A31: 29 | C31: C2338 | D31: 2300 | E31: 3800 | F31: 14 | G31: 8.17 | H31: =F31*G31 -> 114.38 | I31: ='C2430'!B371 -> 1459.77 | K31: =I31*H31 -> 166968.49
A32: 30 | C32: C2430 | D32: 2400 | E32: 3000 | F32: 6 | G32: 6.58 | H32: =F32*G32 -> 39.48 | I32: ='C2430'!B371 -> 1459.77 | K32: =I32*H32 -> 57631.72
A33: 31 | C33: C2722 | D33: 2700 | E33: 2150 | F33: 2 | G33: 5.02 | H33: =F33*G33 -> 10.04 | I33: ='C2430'!B371 -> 1459.77 | K33: =I33*H33 -> 14656.091
A34: 32 | C34: C2727 | D34: 2700 | E34: 2700 | F34: 10 | G34: 6.508 | H34: =F34*G34 -> 65.08 | I34: ='C2430'!B371 -> 1459.77 | K34: =I34*H34 -> 95001.832
A35: 33 | C35: C2730 | D35: 2700 | E35: 3000 | F35: 110 | G35: 7.318 | H35: =F35*G35 -> 804.98 | I35: ='C2430'!B371 -> 1459.77 | K35: =I35*H35 -> 1175085.7
A36: 34 | C36: C2735 | D36: 2700 | E36: 3500 | F36: 19 | G36: 8.668 | H36: =F36*G36 -> 164.692 | I36: ='C2430'!B371 -> 1459.77 | K36: =I36*H36 -> 240412.44
A37: 35 | C37: C2730-xf | D37: 2700 | E37: 3000 | F37: 4 | G37: 7.318 | H37: =F37*G37 -> 29.272 | I37: ='C2430'!B371 -> 1459.77 | K37: =I37*H37 -> 42730.387 | L37: 消防救援口
A38: 36 | C38: C2735-G-xf | D38: 2700 | E38: 3500 | F38: 4 | G38: 8.668 | H38: =F38*G38 -> 34.672 | I38: ='C2430'!B371 -> 1459.77 | K38: =I38*H38 -> 50613.145 | L38: 消防救援口，上拱窗户优化为固玻，无需开启
A39: 37 | C39: C2735-BY | D39: 2700 | E39: 3500 | F39: 7 | G39: 8.67 | H39: =F39*G39 -> 60.69 | I39: ='C2735-G'!B371 -> 1219.49 | K39: =I39*H39 -> 74010.848 | L39: 局部采用防雨百叶
A40: 38 | C40: C1830-G | D40: 1800 | E40: 3000 | F40: 4 | G40: 5.05 | H40: =F40*G40 -> 20.2 | I40: ='C2735-G'!B371 -> 1219.49 | K40: =I40*H40 -> 24633.698 | L40: 上拱窗户优化为固玻，无需开启
...

Sheet 4#楼工程量统计
A1: 4#工程量统计
A2: 序号 | B2: 类型 | C2: 设计编号 | D2: 洞口宽(mm) | E2: 洞口高(mm) | F2: 数量 | G2: 单樘面积(㎡) | H2: 工程量(㎡) | I2: 成本单价 | J2: 成本合价 | K2: 备注 | L2: 截图
A3: 1 | B3: 外门 | C3: WM2038 | D3: 2000 | E3: 3800 | F3: 5 | G3: 7.17 | H3: =F3*G3 -> 35.85 | I3: ='WM2038'!B371 -> 1143.12 | J3: =I3*H3 -> 40980.852 | N3: 序号 | O3: 窗型 | P3: 面积 | Q3: 成本单价 | R3: 成本合价
A4: 2 | C4: WM2338 | D4: 2300 | E4: 3800 | F4: 6 | G4: 8.17 | H4: =F4*G4 -> 49.02 | I4: ='WM2038'!B371 -> 1143.12 | J4: =I4*H4 -> 56035.742 | N4: 1 | O4: 65F铝合金门 | P4: =SUM(H3:H7) -> 107.78 | Q4: =R4/P4 -> 1184.9823 | R4: =SUM(J3:J7) -> 127717.39
A5: 3 | C5: WM2038-1 | D5: 2000 | E5: 3800 | F5: 1 | G5: 7.17 | H5: =F5*G5 -> 7.17 | I5: ='WM2038'!B371 -> 1143.12 | J5: =I5*H5 -> 8196.1704 | N5: 2 | O5: 65F铝合金窗 | P5: =SUM(H8:H15) -> 644.52 | Q5: =R5/P5 -> 1537.8533 | R5: =SUM(J8:J15) -> 991177.19
A6: 4 | B6: 外门联窗 | C6: MLC2030 | D6: 200 | E6: 3000 | F6: 2 | G6: 5.57 | H6: =F6*G6 -> 11.14 | I6: ='MLC2030'!B371 -> 1514.75 | J6: =I6*H6 -> 16874.315 | N6: 3 | O6: 125铝合金幕墙
A7: 5 | C7: MLC2522 | D7: 2500 | E7: 2200 | F7: 1 | G7: 4.6 | H7: =F7*G7 -> 4.6 | I7: ='MLC2522'!B371 -> 1223.98 | J7: =I7*H7 -> 5630.308 | N7: 4 | O7: 铝合金百叶窗 | P7: =SUM(H16:H22) -> 18.38 | Q7: =R7/P7 -> 964 | R7: =SUM(J16:J22) -> 17718.32
A8: 6 | B8: 平开窗 | C8: C2030 | D8: 2000 | E8: 3000 | F8: 12 | G8: 5.57 | H8: =F8*G8 -> 66.84 | I8: ='C2330'!B371 -> 1501.59 | J8: =I8*H8 -> 100366.28 | N8: 5 | O8: 通透格栅
A9: 7 | C9: C2038 | D9: 2000 | E9: 3B00 | F9: 5 | G9: 7.17 | H9: =F9*G9 -> 35.85 | I9: ='C2330'!B371 -> 1501.59 | J9: =I9*H9 -> 53832.001 | N9: 6 | O9: 防蚊纱窗 | P9: =SUM(H23) -> 123.818
A10: 8 | C10: C2330 | D10: 2300 | E10: 3000 | F10: 36 | G10: 6.33 | H10: =F10*G10 -> 227.88 | I10: ='C2330'!B371 -> 1501.59 | J10: =I10*H10 -> 342182.33 | N10: 7 | O10: 阳台铝合金栏杆m
A11: 9 | C11: C2338 | D11: 2300 | E11: 3800 | F11: 18 | G11: 8.17 | H11: =F11*G11 -> 147.06 | I11: ='C2330'!B371 -> 1501.59 | J11: =I11*H11 -> 220823.83 | N11: 8 | O11: 穿孔铝单板
A12: 10 | C12: C2038-BY | D12: 2000 | E12: 3800 | F12: 5 | G12: 7.17 | H12: =F12*G12 -> 35.85 | I12: ='C2330'!B371 -> 1501.59 | J12: =I12*H12 -> 53832.001 | N12: 9 | P12: =SUM(P4:P8) -> 770.68 | Q12: =R12/P12 -> 1474.8182 | R12: =SUM(R4:R7) -> 1136612.9
A13: 11 | C13: C2338-BY | D13: 2300 | E13: 3800 | F13: 11 | G13: 8.17 | H13: =F13*G13 -> 89.87 | I13: ='C2330'!B371 -> 1501.59 | J13: =I13*H13 -> 134947.89
A14: 12 | B14: 固定窗 | C14: XC1014 | D14: 1000 | E14: 1400 | F14: 30 | G14: 1.1 | H14: =F14*G14 -> 33 | I14: ='C1014'!B371 -> 2372.44 | J14: =I14*H14 -> 78290.52
A15: 13 | C15: GDC2338 | D15: 2300 | E15: 3800 | F15: 1 | G15: 8.17 | H15: =F15*G15 -> 8.17 | I15: ='GDC2338'!B371 -> 844.84 | J15: =I15*H15 -> 6902.3428
A16: 14 | B16: 百叶门窗 铝合金防雨百叶，通风率不小于70% | C16: BYC0507 | D16: 500 | E16: 700 | F16: 1 | G16: =0.5*0.7 -> 0.35 | H16: =F16*G16 -> 0.35 | I16: ='BYC0809'!G62 -> 964 | J16: =I16*H16 -> 337.4
A17: 15 | C17: BYC0809 | D17: 800 | E17: 900 | F17: 1 | G17: =0.8*0.9 -> 0.72 | H17: =F17*G17 -> 0.72 | I17: ='BYC0809'!G62 -> 964 | J17: =I17*H17 -> 694.08
A18: 16 | C18: BYC0907 | D18: 900 | E18: 700 | F18: 2 | G18: =0.9*0.7 -> 0.63 | H18: =F18*G18 -> 1.26 | I18: ='BYC0809'!G62 -> 964 | J18: =I18*H18 -> 1214.64
A19: 17 | C19: BYC2004 | D19: 2000 | E19: 400 | F19: 5 | G19: =2*0.4 -> 0.8 | H19: =F19*G19 -> 4 | I19: ='BYC0809'!G62 -> 964 | J19: =I19*H19 -> 3856
A20: 18 | C20: BYC2303 | D20: 230 | E20: 300 | F20: 5 | G20: =2.3*0.3 -> 0.69 | H20: =F20*G20 -> 3.45 | I20: ='BYC0809'!G62 -> 964 | J20: =I20*H20 -> 3325.8
A21: 19 | C21: BYC2805 | D21: 2800 | E21: 500 | F21: 2 | G21: =2.8*0.5 -> 1.4 | H21: =F21*G21 -> 2.8 | I21: ='BYC0809'!G62 -> 964 | J21: =I21*H21 -> 2699.2
A22: 20 | C22: BYC2905 | D22: 2900 | E22: 500 | F22: 4 | G22: =2.9*0.5 -> 1.45 | H22: =F22*G22 -> 5.8 | I22: ='BYC0809'!G62 -> 964 | J22: =I22*H22 -> 5591.2
A23: 21 | B23: 防蚊纱窗 | G23: 0.4 | H23: =SUM(H6:H13)*20% -> 123.818 | J23: =I23*H23 -> 0
A24: 22 | B24: 合计 | F24: =SUM(F3:F23) -> 153 | H24: =SUM(H3:H22) -> 770.68 | I24: =J24/H24 -> 1474.8182 | J24: =SUM(J3:J23) -> 1136612.9

Sheet 5#楼工程量统计
A1: 5#工程量统计
A2: 序号 | B2: 类型 | C2: 设计编号 | D2: 洞口宽(mm) | E2: 洞口高(mm) | F2: 数量 | G2: 单樘面积(㎡) | H2: 工程量(㎡) | I2: 成本单价 | J2: 成本合价 | K2: 备注
A3: 1 | B3: 防雨百叶窗 | C3: BYC0304 | D3: 300 | E3: 400 | F3: 6 | G3: =0.3*0.4 -> 0.12 | H3: =F3*G3 -> 0.72 | I3: ='BYC0624'!G62 -> 1004 | J3: =I3*H3 -> 722.88 | K3: 通风率不小于70%
A4: 2 | B4: 防雨百叶窗 | C4: BYC0305 | D4: 300 | E4: 500 | F4: 2 | G4: =0.3*0.5 -> 0.15 | H4: =F4*G4 -> 0.3 | I4: ='BYC0624'!G62 -> 1004 | J4: =I4*H4 -> 301.2 | M4: 序号 | N4: 窗型 | O4: 面积 | P4: 成本单价 | Q4: 成本合价
A5: 3 | B5: 防雨百叶窗 | C5: BYC0404 | D5: 400 | E5: 400 | F5: 3 | G5: =0.4*0.4 -> 0.16 | H5: =F5*G5 -> 0.48 | I5: ='BYC0624'!G62 -> 1004 | J5: =I5*H5 -> 481.92 | M5: 1 | N5: 65F铝合金门 | O5: =SUM(H24:H26,H28:H32) -> 1236.605 | P5: =Q5/O5 -> 1406.672 | Q5: =SUM(J24:J26,J28:J32) -> 1739497.6
A6: 4 | B6: 防雨百叶窗 | C6: BYC0704 | D6: 700 | E6: 400 | F6: 44 | G6: =0.7*0.4 -> 0.28 | H6: =F6*G6 -> 12.32 | I6: ='BYC0624'!G62 -> 1004 | J6: =I6*H6 -> 12369.28 | M6: 2 | N6: 65F铝合金窗 | O6: =SUM(H16:H22) -> 174.03 | P6: =Q6/O6 -> 1589.7681 | Q6: =SUM(J16:J22) -> 276667.34
A7: 5 | B7: 防雨百叶窗 | C7: BYC1212 | D7: 1200 | E7: 1200 | F7: 2 | G7: =1.2*1.2 -> 1.44 | H7: =F7*G7 -> 2.88 | I7: ='BYC0624'!G62 -> 1004 | J7: =I7*H7 -> 2891.52 | M7: 3 | N7: 125铝合金幕墙 | O7: =SUM(H23,H27) -> 211.68 | P7: =Q7/O7 -> 1118.645 | Q7: =SUM(J23,J27) -> 236794.77
A8: 6 | B8: 防雨百叶窗 | C8: BYC1204 | D8: 1200 | E8: 400 | F8: 4 | G8: =1.2*0.4 -> 0.48 | H8: =F8*G8 -> 1.92 | I8: ='BYC0624'!G62 -> 1004 | J8: =I8*H8 -> 1927.68 | M8: 4 | N8: 铝合金百叶窗 | O8: =SUM(H3:H15) -> 329.84 | P8: =Q8/O8 -> 1004 | Q8: =SUM(J3:J15) -> 331159.36
A9: 7 | B9: 防雨百叶窗 | C9: BYC0410 | D9: 400 | E9: 1000 | F9: 15 | G9: =0.4*1 -> 0.4 | H9: =F9*G9 -> 6 | I9: ='BYC0624'!G62 -> 1004 | J9: =I9*H9 -> 6024 | M9: 5 | N9: 通透格栅
A10: 8 | B10: 防雨百叶窗 | C10: BYC1720 | D10: 1700 | E10: 2000 | F10: 1 | G10: =1.7*2 -> 3.4 | H10: =F10*G10 -> 3.4 | I10: ='BYC0624'!G62 -> 1004 | J10: =I10*H10 -> 3413.6 | M10: 6 | N10: 防蚊纱窗 | O10: =SUM(H33) -> 121.6
A11: 9 | B11: 防雨百叶窗 | C11: BYC2338 | D11: 2300 | E11: 3800 | F11: 2 | G11: 8.17 | H11: =F11*G11 -> 16.34 | I11: ='BYC0624'!G62 -> 1004 | J11: =I11*H11 -> 16405.36 | M11: 7 | N11: 阳台铝合金栏杆m | O11: =SUM(H34) -> 483.3
A12: 10 | B12: 防雨百叶窗 | C12: BYC1720-1 | D12: 1650 | E12: 2000 | F12: 1 | G12: =1.65*2 -> 3.3 | H12: =F12*G12 -> 3.3 | I12: ='BYC0624'!G62 -> 1004 | J12: =I12*H12 -> 3313.2 | M12: 8 | N12: 穿孔铝单板 | O12: =SUM(H35) -> 135
A13: 11 | B13: 防雨百叶窗 | C13: BYC1522 | D13: 1500 | E13: 2200 | F13: 1 | G13: =1.5*2.2 -> 3.3 | H13: =F13*G13 -> 3.3 | I13: ='BYC0624'!G62 -> 1004 | J13: =I13*H13 -> 3313.2 | M13: 9 | O13: =SUM(O5:O9) -> 1952.155 | P13: =Q13/O13 -> 1323.7264 | Q13: =SUM(Q5:Q8) -> 2584119.1
A14: 12 | B14: 防雨百叶窗 | C14: BYC2012 | D14: 2000 | E14: 1200 | F14: 1 | G14: =1.2*2 -> 2.4 | H14: =F14*G14 -> 2.4 | I14: ='BYC0624'!G62 -> 1004 | J14: =I14*H14 -> 2409.6
A15: 13 | B15: 防雨百叶门 | C15: BYC0624 | D15: 600 | E15: 2400 | F15: 192 | G15: =0.6*2.4 -> 1.44 | H15: =F15*G15 -> 276.48 | I15: ='BYC0624'!G62 -> 1004 | J15: =I15*H15 -> 277585.92
A16: 14 | B16: 外窗 | C16: C0410 | D16: 400 | E16: 1000 | F16: 9 | G16: =0.4*1 -> 0.4 | H16: =F16*G16 -> 3.6 | I16: ='C0410'!B371 -> 1733.48 | J16: =I16*H16 -> 6240.528
A17: 15 | B17: 外窗 | C17: GDC1212 | D17: 1200 | E17: 1200 | F17: 2 | G17: =1.2*1.2 -> 1.44 | H17: =F17*G17 -> 2.88 | I17: ='GDC1212'!B371 -> 800.5 | J17: =I17*H17 -> 2305.44
A18: 16 | B18: 外窗 | C18: C1217 | D18: 1200 | E18: 1700 | F18: 2 | G18: 1.6 | H18: =F18*G18 -> 3.2 | I18: ='C1014'!B371 -> 2372.44 | J18: =I18*H18 -> 7591.808
A19: 17 | B19: 外窗 | C19: C1938 | D19: 1900 | E19: 3800 | F19: 2 | G19: 6.83 | H19: =F19*G19 -> 13.66 | I19: ='C2330'!B371 -> 1501.59 | J19: =I19*H19 -> 20511.719
A20: 18 | B20: 外窗 | C20: GDC2327 | D20: 2300 | E20: 2650 | F20: 6 | G20: =2.3*2.65 -> 6.095 | H20: =F20*G20 -> 36.57 | I20: ='C2327'!B371 -> 1662.65 | J20: =I20*H20 -> 60803.111
A21: 19 | B21: 外窗 | C21: C2327 | D21: 2300 | E21: 2650 | F21: 8 | G21: =2.3*2.65 -> 6.095 | H21: =F21*G21 -> 48.76 | I21: ='C2327'!B371 -> 1662.65 | J21: =I21*H21 -> 81070.814
A22: 20 | B22: 外窗 | C22: C2338 | D22: 2300 | E22: 3800 | F22: 8 | G22: 8.17 | H22: =F22*G22 -> 65.36 | I22: ='C2330'!B371 -> 1501.59 | J22: =I22*H22 -> 98143.922
A23: 21 | B23: 外窗框 | C23: C2360 | D23: 2300 | E23: 6000 | F23: 12 | G23: 13.23 | H23: =F23*G23 -> 158.76 | I23: ='C2360'!G126 -> 1096.81 | J23: =I23*H23 -> 174129.56 | L23: 125幕墙
A24: 22 | B24: 外门联窗 | C24: MLC2324 | D24: 2300 | E24: 2400 | F24: 190 | G24: =2.3*2.4 -> 5.52 | H24: =F24*G24 -> 1048.8 | I24: ='MLC2324'!B371 -> 1417.48 | J24: =I24*H24 -> 1486653
A25: 23 | B25: 外门联窗 | C25: MLC2327 | D25: 2300 | E25: 2650 | F25: 11 | G25: =2.3*2.65 -> 6.095 | H25: =F25*G25 -> 67.045 | I25: ='MLC2324'!B371 -> 1417.48 | J25: =I25*H25 -> 95034.947
A26: 24 | B26: 外门联窗 | C26: MLC2324A | D26: 2300 | E26: 2400 | F26: 2 | G26: =2.3*2.4 -> 5.52 | H26: =F26*G26 -> 11.04 | I26: ='MLC2324'!B371 -> 1417.48 | J26: =I26*H26 -> 15648.979
A27: 25 | B27: 外门联窗框 | C27: MLC2360 | D27: 2300 | E27: 6000 | F27: 4 | G27: 13.23 | H27: =F27*G27 -> 52.92 | I27: ='MLC2360'!G126 -> 1184.15 | J27: =I27*H27 -> 62665.218 | L27: 125幕墙
A28: 26 | B28: 外门 | C28: WM1122 | D28: 1100 | E28: 2200 | F28: 3 | G28: =1.1*2.2 -> 2.42 | H28: =F28*G28 -> 7.26 | I28: ='WM1325'!B371 -> 1524.32 | J28: =I28*H28 -> 11066.563
A29: 27 | B29: 外门 | C29: WM1222 | D29: 1200 | E29: 2200 | F29: 2 | G29: =1.2*2.2 -> 2.64 | H29: =F29*G29 -> 5.28 | I29: ='WM1325'!B371 -> 1524.32 | J29: =I29*H29 -> 8048.4096
A30: 28 | B30: 外门 | C30: WM1325 | D30: 1300 | E30: 2450 | F30: 2 | G30: =1.3*2.45 -> 3.185 | H30: =F30*G30 -> 6.37 | I30: ='WM1325'!B371 -> 1524.32 | J30: =I30*H30 -> 9709.9184
A31: 29 | B31: 外门 | C31: WM1824 | D31: 1800 | E31: 2400 | F31: 4 | G31: =1.8*2.4 -> 4.32 | H31: =F31*G31 -> 17.28 | I31: ='WM1325'!B371 -> 1524.32 | J31: =I31*H31 -> 26340.25
A32: 30 | B32: 外门 | C32: WM2338 | D32: 2300 | E32: 3800 | F32: 9 | G32: 8.17 | H32: =F32*G32 -> 73.53 | I32: ='WM2338'!B371 -> 1183.13 | J32: =I32*H32 -> 86995.549
A33: 31 | B33: 防蚊纱窗 | C33: MLC2324 | D33: 400 | E33: 800 | F33: =190*2 -> 380 | G33: =0.4*0.8 -> 0.32 | H33: =F33*G33 -> 121.6
A34: 32 | B34: 阳台铝合金栏杆m | F34: 3 | G34: =(160.55+81.1)*2/3 -> 161.1 | H34: =F34*G34 -> 483.3
A35: 33 | B35: =[29]工程量清单计价表!B129 -> 穿孔铝单板 | F35: 18 | G35: 7.5 | H35: =F35*G35 -> 135
A36: 34 | B36: 合计 | F36: =SUM(F3:F32) -> 550 | H36: =SUM(H3:H32) -> 1952.155 | I36: =J36/H36 -> 1323.7264 | J36: =SUM(J3:J32) -> 2584119.1

Sheet 6#楼工程量统计 
A1: 6#工程量统计
A2: 序号 | B2: 类型 | C2: 设计编号 | D2: 洞口宽(mm) | E2: 洞口高(mm) | F2: 数量 | G2: 单樘面积(㎡) | H2: 工程量(㎡) | I2: 成本单价 | J2: 成本合价 | K2: 备注
A3: 1 | B3: 防雨百叶窗 | C3: BYC0304 | D3: 300 | E3: 400 | F3: 14 | G3: =0.3*0.4 -> 0.12 | H3: =F3*G3 -> 1.68 | I3: ='BYC0624'!G62 -> 1004 | J3: =I3*H3 -> 1686.72 | K3: 通风率不小于70%
A4: 2 | B4: 防雨百叶窗 | C4: BYC0504 | D4: 450 | E4: 400 | F4: 2 | G4: =0.45*0.4 -> 0.18 | H4: =F4*G4 -> 0.36 | I4: ='BYC0624'!G62 -> 1004 | J4: =I4*H4 -> 361.44 | M4: 序号 | N4: 窗型 | O4: 面积 | P4: 成本单价 | Q4: 成本合价
A5: 3 | B5: 防雨百叶窗 | C5: BYC0704 | D5: 700 | E5: 400 | F5: 88 | G5: =0.7*0.4 -> 0.28 | H5: =F5*G5 -> 24.64 | I5: ='BYC0624'!G62 -> 1004 | J5: =I5*H5 -> 24738.56 | M5: 1 | N5: 65F铝合金门 | O5: =SUM(H18:H28) -> 2384.43 | P5: =Q5/O5 -> 1463.4744 | Q5: =SUM(J18:J28) -> 3489552.3
A6: 4 | B6: 防雨百叶窗 | C6: BYC1004 | D6: 950 | E6: 400 | F6: 2 | G6: =0.95*0.4 -> 0.38 | H6: =F6*G6 -> 0.76 | I6: ='BYC0624'!G62 -> 1004 | J6: =I6*H6 -> 763.04 | M6: 2 | N6: 65F铝合金窗 | O6: =SUM(H10:H16) -> 393.89 | P6: =Q6/O6 -> 1594.5882 | Q6: =SUM(J10:J16) -> 628092.36
A7: 5 | B7: 防雨百叶窗 | C7: BYC1212 | D7: 1200 | E7: 1200 | F7: 4 | G7: =1.2*1.2 -> 1.44 | H7: =F7*G7 -> 5.76 | I7: ='BYC0624'!G62 -> 1004 | J7: =I7*H7 -> 5783.04 | M7: 3 | N7: 125铝合金幕墙 | O7: =SUM(H17,H29) -> 277.83 | P7: =Q7/O7 -> 1105.1281 | Q7: =SUM(J17,J29) -> 307037.74
A8: 6 | B8: 防雨百叶窗 | C8: BYC2220 | D8: 2200 | E8: 2000 | F8: 4 | G8: =2*2.2 -> 4.4 | H8: =F8*G8 -> 17.6 | I8: ='BYC0624'!G62 -> 1004 | J8: =I8*H8 -> 17670.4 | M8: 4 | N8: 铝合金百叶窗 | O8: =SUM(H3:H9) -> 603.76 | P8: =Q8/O8 -> 1004 | Q8: =SUM(J3:J9) -> 606175.04
A9: 7 | B9: 防雨百叶门 | C9: BYM0624 | D9: 600 | E9: 2400 | F9: 384 | G9: =0.6*2.4 -> 1.44 | H9: =F9*G9 -> 552.96 | I9: ='BYC0624'!G62 -> 1004 | J9: =I9*H9 -> 555171.84 | M9: 5 | N9: 通透格栅
A10: 8 | B10: 外窗 | C10: C0410 | D10: 400 | E10: 1200 | F10: 15 | G10: =0.4*1.2 -> 0.48 | H10: =F10*G10 -> 7.2 | I10: ='C0410'!B371 -> 1733.48 | J10: =I10*H10 -> 12481.056 | M10: 6 | N10: 防蚊纱窗 | O10: =SUM(H30) -> 128
A11: 9 | B11: 外窗 | C11: C1212 | D11: 1200 | E11: 1200 | F11: 4 | G11: =1.2*1.2 -> 1.44 | H11: =F11*G11 -> 5.76 | I11: ='GDC1212'!B371 -> 800.5 | J11: =I11*H11 -> 4610.88 | M11: 7 | N11: 阳台铝合金栏杆m | O11: =SUM(H31) -> 985.8
A12: 10 | B12: 外窗 | C12: C1217 | D12: 1200 | E12: 1700 | F12: 12 | G12: 1.6 | H12: =F12*G12 -> 19.2 | I12: ='C1014'!B371 -> 2372.44 | J12: =I12*H12 -> 45550.848 | M12: 8 | N12: 穿孔铝单板 | O12: =SUM(H32) -> 210
A13: 11 | B13: 外窗 | C13: C1938 | D13: 1900 | E13: 3800 | F13: 4 | G13: 6.83 | H13: =F13*G13 -> 27.32 | I13: ='C2330'!B371 -> 1501.59 | J13: =I13*H13 -> 41023.439 | M13: 9 | O13: =SUM(O5:O9) -> 3659.91 | P13: =Q13/O13 -> 1374.585 | Q13: =SUM(Q5:Q8) -> 5030857.4
A14: 12 | B14: 外窗 | C14: C2127 | D14: 2100 | E14: 2650 | F14: 15 | G14: =2.1*2.65 -> 5.565 | H14: =F14*G14 -> 83.475 | I14: ='C2327'!B371 -> 1662.65 | J14: =I14*H14 -> 138789.71
A15: 13 | B15: 外窗 | C15: C2327 | D15: 2300 | E15: 2650 | F15: 9 | G15: =2.3*2.65 -> 6.095 | H15: =F15*G15 -> 54.855 | I15: ='C2327'!B371 -> 1662.65 | J15: =I15*H15 -> 91204.666
A16: 14 | B16: 外窗 | C16: C2338 | D16: 2300 | E16: 3800 | F16: 24 | G16: 8.17 | H16: =F16*G16 -> 196.08 | I16: ='C2330'!B371 -> 1501.59 | J16: =I16*H16 -> 294431.77
A17: 15 | B17: 外门框 | C17: C2360 | D17: 2300 | E17: 6000 | F17: 19 | G17: 13.23 | H17: =F17*G17 -> 251.37 | I17: ='C2360'!G126 -> 1096.81 | J17: =I17*H17 -> 275705.13 | L17: 125幕墙
A18: 16 | B18: 外门 | C18: WM1122 | D18: 1100 | E18: 2200 | F18: 4 | G18: =1.1*2.2 -> 2.42 | H18: =F18*G18 -> 9.68 | I18: ='WM1325'!B371 -> 1524.32 | J18: =I18*H18 -> 14755.418
A19: 17 | B19: 外门 | C19: WM1522 | D19: 1500 | E19: 2200 | F19: 2 | G19: =1.5*2.2 -> 3.3 | H19: =F19*G19 -> 6.6 | I19: ='WM1325'!B371 -> 1524.32 | J19: =I19*H19 -> 10060.512
A20: 18 | B20: 外门 | C20: WM2324 | D20: 2300 | E20: 2400 | F20: 2 | G20: =2.3*2.4 -> 5.52 | H20: =F20*G20 -> 11.04 | I20: ='WM1325'!B371 -> 1524.32 | J20: =I20*H20 -> 16828.493 | K20: 其中2个为消防救援窗口
A21: 19 | B21: 外门 | C21: WM2338 | D21: 2300 | E21: 3800 | F21: 20 | G21: 8.17 | H21: =F21*G21 -> 163.4 | I21: ='WM2338'!B371 -> 1183.13 | J21: =I21*H21 -> 193323.44
A22: 20 | B22: 外门联窗 | C22: MLC2124 | D22: 2100 | E22: 2400 | F22: 160 | G22: =2.1*2.4 -> 5.04 | H22: =F22*G22 -> 806.4 | I22: ='MLC2124'!B371 -> 1599.79 | J22: =I22*H22 -> 1290070.7
A23: 21 | B23: 外门联窗 | C23: MLC2324 | D23: 2300 | E23: 2400 | F23: =220-F24 -> 180 | G23: =2.3*2.4 -> 5.52 | H23: =F23*G23 -> 993.6 | I23: =MLC2324A!B371 -> 1415.54 | J23: =I23*H23 -> 1406480.5
A24: 22 | B24: 外门联窗 | C24: MLC2324 | D24: 2300 | E24: 2400 | F24: 40 | G24: =2.3*2.4 -> 5.52 | H24: =F24*G24 -> 220.8 | I24: ='MLC2324'!B371 -> 1417.48 | J24: =I24*H24 -> 312979.58 | K24: 40个为消防救援窗口
A25: 23 | B25: 外门联窗 | C25: MLC2127 | D25: 2100 | E25: 2650 | F25: 14 | G25: =2.1*2.65 -> 5.565 | H25: =F25*G25 -> 77.91 | I25: ='MLC2324'!B371 -> 1417.48 | J25: =I25*H25 -> 110435.87
A26: 24 | B26: 外门联窗 | C26: MLC2327 | D26: 2300 | E26: 2650 | F26: 8 | G26: =2.3*2.65 -> 6.095 | H26: =F26*G26 -> 48.76 | I26: ='MLC2324'!B371 -> 1417.48 | J26: =I26*H26 -> 69116.325
A27: 25 | B27: 外门联窗 | C27: MLC2324A | D27: 2300 | E27: 2400 | F27: 4 | G27: =2.3*2.4 -> 5.52 | H27: =F27*G27 -> 22.08 | I27: =MLC2324A!B371 -> 1415.54 | J27: =I27*H27 -> 31255.123
A28: 26 | B28: 外门联窗 | C28: MLC2355 | D28: 2300 | E28: 5500 | F28: 2 | G28: 12.08 | H28: =F28*G28 -> 24.16 | I28: ='MLC2324'!B371 -> 1417.48 | J28: =I28*H28 -> 34246.317 | K28: 此门联窗为消防救援窗口
A29: 27 | B29: 外门联窗框 | C29: MLC2360 | D29: 2300 | E29: 6000 | F29: 2 | G29: 13.23 | H29: =F29*G29 -> 26.46 | I29: ='MLC2360'!G126 -> 1184.15 | J29: =I29*H29 -> 31332.609 | L29: 125幕墙
A30: 28 | B30: 防蚊纱窗 | C30: MLC2124 | D30: 500 | E30: 800 | F30: =160*2 -> 320 | G30: =0.5*0.8 -> 0.4 | H30: =F30*G30 -> 128
A31: 29 | B31: 阳台铝合金栏杆m | F31: 3 | G31: =(329.24+163.66)*2/3 -> 328.6 | H31: =F31*G31 -> 985.8
A32: 30 | B32: =[29]工程量清单计价表!B161 -> 穿孔铝单板 | F32: 28 | G32: 7.5 | H32: =F32*G32 -> 210
A33: 31 | B33: 合计 | F33: =SUM(F3:F29) -> 1038 | H33: =SUM(H3:H29) -> 3659.91 | I33: =J33/H33 -> 1374.585 | J33: =SUM(J3:J29) -> 5030857.4

Sheet 8#楼工程量统计
A1: 8#工程量统计
A2: 序号 | B2: 类型 | C2: 设计编号 | D2: 洞口宽(mm) | E2: 洞口高(mm) | F2: 数量 | G2: 单樘面积(㎡) | H2: 工程量(㎡) | I2: 成本单价 | J2: 成本合价 | K2: 备注
A3: 1 | B3: 外门 | C3: WM1127 | D3: 1100 | E3: 2650 | F3: 4 | G3: 2.785 | H3: =F3*G3 -> 11.14 | I3: ='WM1127'!B371 -> 1663.91 | J3: =I3*H3 -> 18535.957
A4: 2 | C4: WM1130-XF | D4: 1100 | E4: 3000 | F4: 2 | G4: 3.17 | H4: =F4*G4 -> 6.34 | I4: ='WM1127'!B371 -> 1663.91 | J4: =I4*H4 -> 10549.189 | M4: 序号 | N4: 窗型 | O4: 面积 | P4: 成本单价 | Q4: 成本合价
A5: 3 | C5: WM1224 | D5: 1200 | E5: 2400 | F5: 1 | G5: =1.2*2.4 -> 2.88 | H5: =F5*G5 -> 2.88 | I5: ='WM1127'!B371 -> 1663.91 | J5: =I5*H5 -> 4792.0608 | M5: 1 | N5: 65F铝合金门 | O5: =SUM(H3:H6) -> 40.91 | P5: =Q5/O5 -> 1663.91 | Q5: =SUM(J3:J6) -> 68070.558
A6: 4 | C6: WM1840 | D6: 1800 | E6: 4000 | F6: 3 | G6: 6.85 | H6: =F6*G6 -> 20.55 | I6: ='WM1127'!B371 -> 1663.91 | J6: =I6*H6 -> 34193.351 | M6: 2 | N6: 65F铝合金窗 | O6: =SUM(H16:H35) -> 979.36 | P6: =Q6/O6 -> 1507.9929 | Q6: =SUM(J16:J35) -> 1476867.9
A7: 5 | C7: WM2888 | D7: 2800 | E7: 8800 | F7: 4 | G7: 23.8 | H7: =F7*G7 -> 95.2 | I7: ='MLC2888'!G126 -> 1722.2 | J7: =I7*H7 -> 163953.44 | L7: 125幕墙 | M7: 3 | N7: 125铝合金幕墙 | O7: =SUM(H7:H8) -> 190.4 | P7: =Q7/O7 -> 1722.2 | Q7: =SUM(J7:J8) -> 327906.88
A8: 6 | C8: WM2888-w | D8: 2800 | E8: 8800 | F8: 4 | G8: 23.8 | H8: =F8*G8 -> 95.2 | I8: ='MLC2888'!G126 -> 1722.2 | J8: =I8*H8 -> 163953.44 | K8: 无障碍外门 | L8: 125幕墙 | M8: 4 | N8: 铝合金百叶窗 | O8: =SUM(H9:H15) -> 54.83 | P8: =Q8/O8 -> 794 | Q8: =SUM(J9:J15) -> 43535.02
A9: 7 | B9: 百叶窗 铝合金防雨百叶 | C9: BYC0804 | D9: 800 | E9: 350 | F9: 4 | G9: =0.8*0.35 -> 0.28 | H9: =F9*G9 -> 1.12 | I9: ='BYC1610'!G62 -> 794 | J9: =I9*H9 -> 889.28 | M9: 5 | N9: 通透格栅 | O9: =SUM(H36:H37) -> 174.42 | P9: =Q9/O9 -> 1117.43 | Q9: =SUM(J36:J37) -> 194902.14
A10: 8 | C10: BYC1130 | D10: 1100 | E10: 3000 | F10: 5 | G10: 3.17 | H10: =F10*G10 -> 15.85 | I10: ='BYC1610'!G62 -> 794 | J10: =I10*H10 -> 12584.9 | M10: 6 | N10: 防蚊纱窗 | O10: =SUM(H38) -> 162.69
A11: 9 | C11: BYC1209 | D11: 1200 | E11: 900 | F11: 2 | G11: =1.2*0.9 -> 1.08 | H11: =F11*G11 -> 2.16 | I11: ='BYC1610'!G62 -> 794 | J11: =I11*H11 -> 1715.04 | M11: 7 | N11: 阳台铝合金栏杆m | O11: =SUM(H39) -> 168
A12: 10 | C12: BYC1508 | D12: 1500 | E12: 800 | F12: 1 | G12: =1.5*0.8 -> 1.2 | H12: =F12*G12 -> 1.2 | I12: ='BYC1610'!G62 -> 794 | J12: =I12*H12 -> 952.8 | M12: 8 | N12: 穿孔铝单板
A13: 11 | C13: BYC1610 | D13: 1600 | E13: 1000 | F13: 1 | G13: =1.6*1 -> 1.6 | H13: =F13*G13 -> 1.6 | I13: ='BYC1610'!G62 -> 794 | J13: =I13*H13 -> 1270.4 | M13: 9 | O13: =SUM(O5:O9) -> 1439.92 | P13: =Q13/O13 -> 1466.2499 | Q13: =SUM(Q5:Q12) -> 2111282.5
A14: 12 | C14: BYC2435 | D14: 2400 | E14: 3500 | F14: 2 | G14: 7.78 | H14: =F14*G14 -> 15.56 | I14: ='BYC1610'!G62 -> 794 | J14: =I14*H14 -> 12354.64
A15: 13 | C15: BYC2735 | D15: 2700 | E15: 3500 | F15: 2 | G15: 8.67 | H15: =F15*G15 -> 17.34 | I15: ='BYC1610'!G62 -> 794 | J15: =I15*H15 -> 13767.96
A16: 14 | B16: 外窗 | C16: C1014 | D16: 1000 | E16: 1400 | F16: 17 | G16: 1.1 | H16: =F16*G16 -> 18.7 | I16: ='C1014'!B371 -> 2372.44 | J16: =I16*H16 -> 44364.628 | K16: 固定
A17: 15 | C17: C1125 | D17: 1100 | E17: 2450 | F17: 8 | G17: 2.455 | H17: =F17*G17 -> 19.64 | I17: ='C1127'!B371 -> 1558.89 | J17: =I17*H17 -> 30616.6 | K17: 外平开
A18: 16 | C18: C1127 | D18: 1100 | E18: 2650 | F18: 60 | G18: 2.785 | H18: =F18*G18 -> 167.1 | I18: ='C1127'!B371 -> 1558.89 | J18: =I18*H18 -> 260490.52 | K18: 外平开
A19: 17 | C19: C1130 | D19: 1100 | E19: 3000 | F19: 41 | G19: 3.17 | H19: =F19*G19 -> 129.97 | I19: ='C1127'!B371 -> 1558.89 | J19: =I19*H19 -> 202608.93 | K19: 外平开
A20: 18 | C20: C2430 | D20: 2400 | E20: 3000 | F20: 2 | G20: 6.58 | H20: =F20*G20 -> 13.16 | I20: ='C2430'!B371 -> 1459.77 | J20: =I20*H20 -> 19210.573 | K20: 外平开
A21: 19 | C21: C2435 | D21: 2400 | E21: 3500 | F21: 3 | G21: 7.78 | H21: =F21*G21 -> 23.34 | I21: ='C2430'!B371 -> 1459.77 | J21: =I21*H21 -> 34071.032 | K21: 外平开
A22: 20 | C22: C2729 | D22: 2700 | E22: 2900 | F22: 1 | G22: 7.05 | H22: =F22*G22 -> 7.05 | I22: ='C2430'!B371 -> 1459.77 | J22: =I22*H22 -> 10291.378 | K22: 外平开
A23: 21 | C23: C2735 | D23: 2700 | E23: 3500 | F23: 27 | G23: 8.67 | H23: =F23*G23 -> 234.09 | I23: ='C2430'!B371 -> 1459.77 | J23: =I23*H23 -> 341717.56 | K23: 外平开
A24: 22 | C24: C2740 | D24: 2700 | E24: 4000 | F24: 20 | G24: 10.02 | H24: =F24*G24 -> 200.4 | I24: ='C2430'!B371 -> 1459.77 | J24: =I24*H24 -> 292537.91 | K24: 外平开
A25: 23 | B25: 外窗（局部百叶） | C25: C1814-BY | D25: 1800 | E25: 1400 | F25: 1 | G25: =1.8*1.4 -> 2.52 | H25: =F25*G25 -> 2.52 | I25: ='GDC2338'!B371 -> 844.84 | J25: =I25*H25 -> 2128.9968
A26: 24 | C26: C2438-BY | D26: 2400 | E26: 3800 | F26: 2 | G26: 8.5 | H26: =F26*G26 -> 17 | I26: ='GDC2338'!B371 -> 844.84 | J26: =I26*H26 -> 14362.28
A27: 25 | C27: C2735-BY | D27: 2700 | E27: 3500 | F27: 1 | G27: 8.67 | H27: =F27*G27 -> 8.67 | I27: ='GDC2338'!B371 -> 844.84 | J27: =I27*H27 -> 7324.7628
A28: 26 | C28: C2738-BY | D28: 2700 | E28: 3800 | F28: 1 | G28: 9.48 | H28: =F28*G28 -> 9.48 | I28: ='GDC2338'!B371 -> 844.84 | J28: =I28*H28 -> 8009.0832
A29: 27 | C29: C2740-BY | D29: 2700 | E29: 4000 | F29: 1 | G29: 10.02 | H29: =F29*G29 -> 10.02 | I29: ='GDC2338'!B371 -> 844.84 | J29: =I29*H29 -> 8465.2968
A30: 28 | B30: 高窗 | C30: GC2006 | D30: 1950 | E30: 600 | F30: 31 | G30: =1.95*0.6 -> 1.17 | H30: =F30*G30 -> 36.27 | I30: ='GC2006'!B371 -> 2162.9 | J30: =I30*H30 -> 78448.383 | K30: 固定
A31: 29 | C31: GC2009 | D31: 1950 | E31: 900 | F31: 20 | G31: =1.95*0.9 -> 1.755 | H31: =F31*G31 -> 35.1 | I31: ='GC2006'!B371 -> 2162.9 | J31: =I31*H31 -> 75917.79 | K31: 固定
A32: 30 | B32: 固定窗 | C32: GDC1014 | D32: 1000 | E32: 1400 | F32: 4 | G32: 1.1 | H32: =F32*G32 -> 4.4 | I32: ='C1014'!B371 -> 2372.44 | J32: =I32*H32 -> 10438.736
A33: 31 | C33: GDC1838 | D33: 1800 | E33: 3800 | F33: 1 | G33: 6.49 | H33: =F33*G33 -> 6.49 | I33: ='GDC2338'!B371 -> 844.84 | J33: =I33*H33 -> 5483.0116
A34: 32 | C34: GDC2438 | D34: 2400 | E34: 3800 | F34: 2 | G34: 8.5 | H34: =F34*G34 -> 17 | I34: ='GDC2338'!B371 -> 844.84 | J34: =I34*H34 -> 14362.28
A35: 33 | C35: GDC2738 | D35: 2700 | E35: 3800 | F35: 2 | G35: 9.48 | H35: =F35*G35 -> 18.96 | I35: ='GDC2338'!B371 -> 844.84 | J35: =I35*H35 -> 16018.166
A36: 34 | B36: 通透格栅 | C36: GS7638 | D36: 7600 | E36: 3800 | F36: 4 | G36: =7.6*3.8 -> 28.88 | H36: =F36*G36 -> 115.52 | I36: ='GSM7838'!B371 -> 1117.43 | J36: =I36*H36 -> 129085.51
A37: 35 | C37: GSM7838 | D37: 7750 | E37: 3800 | F37: 2 | G37: =7.75*3.8 -> 29.45 | H37: =F37*G37 -> 58.9 | I37: =I36 -> 1117.43 | J37: =I37*H37 -> 65816.627
A38: 36 | B38: 防蚊纱窗 | G38: 0.48 | H38: =SUM(H16:H24)*20% -> 162.69
A39: 37 | B39: 阳台铝合金栏杆m | F39: 1 | G39: =(67.2+58.8)*2*2/3 -> 168 | H39: =F39*G39 -> 168
A40: 38 | B40: 合计 | F40: =SUM(F3:F37) -> 286 | H40: =SUM(H3:H37) -> 1439.92 | J40: =SUM(J3:J39) -> 2111282.5

Sheet 穿孔铝板
A1: 综合单价分析表1.3
A2: 分项名称： | D2: 3.0mm双面氟碳喷涂穿孔铝单板1 | I2: 计量单位 | J2: m2/元
A3: 序号 | B3: 项目名称 | E3: 材质、规格 | F3: 单位 | G3: 单位 含量 | H3: 单价(元) | I3: 合计(元) | J3: 备注
A4: 一 | B4: 直接费 | C4: 材 料 费 | D4: 3.0mm双面氟碳喷涂穿孔铝单板1 | E4: =VLOOKUP(D4,[30]材料表!$B$4:$F$75,2,0) -> 3.0mm，双面氟碳喷涂 | F4: =VLOOKUP(D4,[30]材料表!$B$4:$F$75,3,0) -> m2 | G4: 1.03 | H4: 320 | I4: =G4*H4 -> 329.6
D5: 40*40*3热镀锌钢方通 | E5: =VLOOKUP(D5,[30]材料表!$B$4:$F$75,2,0) -> 40*40*3 | F5: =VLOOKUP(D5,[30]材料表!$B$4:$F$75,3,0) -> kg | G5: 1.36 | H5: 10 | I5: =G5*H5 -> 13.6
D6: L40*4热镀锌角钢 | E6: =VLOOKUP(D6,[30]材料表!$B$4:$F$75,2,0) -> L40*4 | F6: =VLOOKUP(D6,[30]材料表!$B$4:$F$75,3,0) -> kg | G6: 6.84 | H6: 10 | I6: =G6*H6 -> 68.4
D7: L50*5热镀锌角钢 | E7: =VLOOKUP(D7,[30]材料表!$B$4:$F$75,2,0) -> L50*5 | F7: =VLOOKUP(D7,[30]材料表!$B$4:$F$75,3,0) -> kg | G7: 4.39 | H7: 10 | I7: =G7*H7 -> 43.9
D8: 160*80*8后置埋件 | E8: =VLOOKUP(D8,[30]材料表!$B$4:$F$75,2,0) -> 160*80*8 | F8: =VLOOKUP(D8,[30]材料表!$B$4:$F$75,3,0) -> 块 | G8: 1.86 | H8: 35 | I8: =G8*H8 -> 65.1
D9: M12*160化学锚栓 | E9: =VLOOKUP(D9,[30]材料表!$B$4:$F$75,2,0) -> M12*160 | F9: =VLOOKUP(D9,[30]材料表!$B$4:$F$75,3,0) -> 套 | G9: 1.95 | H9: 10 | I9: =G9*H9 -> 19.5
D10: 硅酮耐候密封胶（500ml/支） | E10: =VLOOKUP(D10,[30]材料表!$B$4:$F$75,2,0) -> 500ml/支 | F10: =VLOOKUP(D10,[30]材料表!$B$4:$F$75,3,0) -> 支 | G10: 1.21 | H10: 16.5 | I10: =G10*H10 -> 19.965
D11: 自攻螺钉 | F11: =VLOOKUP(D11,[30]材料表!$B$4:$F$75,3,0) -> 颗 | G11: 25 | H11: 0.01 | I11: =G11*H11 -> 0.25
D12: 其他材料 | F12: =VLOOKUP(D12,[30]材料表!$B$4:$F$75,3,0) -> 项 | G12: 1 | H12: 10 | I12: =G12*H12 -> 10
D13: 防雷处理 | F13: =VLOOKUP(D13,[30]材料表!$B$4:$F$75,3,0) -> 项 | G13: 1 | H13: 5 | I13: =G13*H13 -> 5
D27: 合计 | I27: =SUM(I4:I26) -> 575.315
C28: 人工费 | F28: 元 | I28: 95
C29: 机械费 | F29: 元 | I29: 10
B30: 本项小计 | F30: 元 | I30: =SUM(I27:I29) -> 680.315
A31: 二 | B31: 管理费 | E31: （一）* 4% | F31: 元 | I31: =I30*$K$2 -> 0
A32: 三 | B32: 利润 | E32: （一+二）* 5% | F32: 元 | I32: =(I31+I30)*5% -> 34.01575
A33: 四 | B33: 税金 | E33: （一+二+三）* 3.43% | F33: 元 | I33: =SUM(I30:I32)*$M$2 -> 0
A34: 五 | B34: 单位造价合计 | E34: （一+二+三+四） | F34: 元 | I34: =SUM(I30:I33) -> 714.33075
A36: 综合单价分析表（每款门窗、幕墙、栏杆都需填报）（此表为门窗的示范表格，请根据各项目特征自行修改主材、辅材、其他费用名称及单位）
A37: 项目： | B37: 铝板 | G37: 综合单价： | H37: =H60 -> 854.51189 | I37: 元/㎡
A38: 序号 | B38: 项目名称 | C38: 材料名称 | D38: 数量 | E38: 单位 | F38: 损耗 | G38: 单价（元） | H38: 合价（元） | I38: 备注 | K38: 面积 | L38: 含量/㎡
A39: 1、 | B39: 主材 | C39: 2.5mm厚氟碳喷涂铝单板 | D39: 1 | E39: kg | F39: 1.03 | G39: 305 | H39: =D39*F39*G39 -> 314.15 | I39: 高士达、蓝天七色 | K39: 1.63 | L39: =1/K39 -> 0.61349693
C40: 50*50*4热镀锌角钢 | D40: =L41*M41*L39 -> 12.932515 | E40: kg | F40: 1.03 | G40: =8.7*1.03 -> 8.961 | H40: =D40*F40*G40 -> 119.36492 | I40: 国产优质 | K40: 胶缝长度 | L40: 50*50*4钢米重 | M40: 米 | N40: 膨胀螺栓
B41: 小计一 | H41: =SUM(H39:H40) -> 433.51492 | K41: 2 | L41: 3.1 | M41: 6.8 | N41: 16
A42: 2、 | B42: 辅材及其他 | C42: M10*100膨胀螺栓 | D42: =N41*L39 -> 9.8159509 | E42: 套 | F42: 1.03 | G42: 2.1 | H42: =D42*F42*G42 -> 21.231902 | I42: 国产优质
C43: 硅酮耐候密封胶(500ml/支) | D43: =K43*1000000/500*L39 -> 1.4723926 | E43: 支 | F43: 1.03 | G43: 20 | H43: =D43*F43*G43 -> 30.331288 | I43: 白云、之江 | K43: 0.0012 | L43: m³
C44: ∅5泡沫棒 | D44: =K41*L39 -> 1.2269939 | E44: ㎡ | F44: 1.03 | G44: 0.86 | H44: =D44*F44*G44 -> 1.0868712 | I44: 国产优质 | J44: 1.03 | K44: =(O36+O37)*4 -> 0
C45: 其它辅材 | D45: 1 | E45: ㎡ | F45: 1 | G45: 15 | H45: =D45*F45*G45 -> 15
C46: 防雷处理 | D46: 1 | E46: ㎡ | F46: 1 | G46: 1.5 | H46: =D46*F46*G46 -> 1.5
C47: 成品保护 | D47: 1 | E47: ㎡ | F47: 1 | G47: 5 | H47: =D47*F47*G47 -> 5
C48: 成品保洁 | D48: 1 | E48: ㎡ | F48: 1 | G48: 8 | H48: =D48*F48*G48 -> 8
C49: 试验费 | D49: 1 | E49: ㎡ | F49: 1 | G49: 5 | H49: =D49*F49*G49 -> 5
C50: 运输费 | D50: 1 | E50: ㎡ | F50: 1 | G50: 15 | H50: =D50*F50*G50 -> 15
C51: 安装人工费 | D51: 1 | E51: ㎡ | F51: 1 | G51: 130 | H51: =D51*F51*G51 -> 130
C52: 加工人工费 | D52: 1 | E52: ㎡ | F52: 1 | G52: 30 | H52: =D52*F52*G52 -> 30
C53: 措施费 | D53: 1 | E53: ㎡ | F53: 1 | G53: 15 | H53: =G53*D53*F53 -> 15 | J53: =SUM(H42:H48)+H41 -> 515.66498
B54: 小计二 | H54: =SUM(H42:H53) -> 277.15006
...

Sheet 栏杆
A1: 综合单价分析表1.7
A2: 分项名称： | D2: 铝合金栏杆(H=1100mm） | I2: 计量单位 | J2: m/元
A3: 序号 | B3: 项目名称 | E3: 材质、规格 | F3: 单位 | G3: 单位 含量 | H3: 单价(元) | I3: 合计(元) | J3: 备注 | K3: 3.16
A4: 一 | B4: 直接费 | C4: 材 料 费 | D4: 铝合金型材扶手，表面氟碳喷涂 | F4: kg | G4: =K4*1.06 -> 0.85754 | H4: =VLOOKUP(D4,[31]材料表!$B$4:$G$80,4,0) -> 33.5 | I4: =G4*H4 -> 28.72759 | K4: =0.38+0.429 -> 0.809
D5: 铝合金型材立柱，表面氟碳喷涂 | F5: kg | G5: =M5/K3*1.06 -> 7.1557967 | H5: =VLOOKUP(D5,[31]材料表!$B$4:$G$80,4,0) -> 33.5 | I5: =G5*H5 -> 239.71919 | K5: 0.785 | L5: =1*22+1.035*5 -> 27.175 | M5: =K5*L5 -> 21.332375
D6: 铝合金型材横梁，表面氟碳喷涂 | F6: kg | G6: =K6*1.06 -> 0.80984 | H6: =VLOOKUP(D6,[31]材料表!$B$4:$G$80,4,0) -> 33.5 | I6: =G6*H6 -> 27.12964 | K6: =0.61+0.154 -> 0.764
D7: 铝合金型材盖板，表面氟碳喷涂 | F7: kg | G7: =K7*1.06 -> 2.36698 | H7: =VLOOKUP(D7,[31]材料表!$B$4:$G$80,4,0) -> 33.5 | I7: =G7*H7 -> 79.29383 | K7: =2.233 -> 2.233
D8: 200*80*8后置埋件 | E8: =VLOOKUP(D8,[31]材料表!$B$4:$G$80,2,0) -> 200*80*8 | F8: =VLOOKUP(D8,[31]材料表!$B$4:$G$80,3,0) -> 块 | G8: =K8/K3 -> 1.5822785 | H8: =VLOOKUP(D8,[31]材料表!$B$4:$G$80,4,0) -> 7.5 | I8: =G8*H8 -> 11.867089 | J8: =VLOOKUP(D8,[31]材料表!$B$4:$G$80,5,0) -> 6.5 | K8: 5
D9: M12*160化学锚栓 | E9: =VLOOKUP(D9,[31]材料表!$B$4:$G$80,2,0) -> M12*160 | F9: =VLOOKUP(D9,[31]材料表!$B$4:$G$80,3,0) -> 套 | G9: =G8*2*1.05 -> 3.3227848 | H9: =VLOOKUP(D9,[31]材料表!$B$4:$G$80,4,0) -> 3.5 | I9: =G9*H9 -> 11.629747 | J9: =VLOOKUP(D9,[31]材料表!$B$4:$G$80,5,0) -> 3.5
D10: M8不锈钢螺栓 | F10: 套 | G10: =K10/K3*1.05 -> 3.3227848 | H10: 1.7 | I10: =G10*H10 -> 5.6487342 | K10: =2*5 -> 10
D11: M6不锈钢螺栓 | F11: 套 | G11: =G10 -> 3.3227848 | H11: 1 | I11: =G11*H11 -> 3.3227848
D12: 6mm厚镀锌钢连接件 | F12: 套 | G12: =G8 -> 1.5822785 | H12: 3.5 | I12: =G12*H12 -> 5.5379747
D13: 2mm厚安装镀锌片 | F13: 块 | G13: =22/K3 -> 6.9620253 | H13: 1.25 | I13: =G13*H13 -> 8.7025316 | K13: =462.31*0.00785 -> 3.6291335 | L13: 0.05 | M13: =K13*L13 -> 0.18145667 | N13: =M13*8 -> 1.4516534
D14: 其他材料 | F14: =VLOOKUP(D14,[31]材料表!$B$4:$G$80,3,0) -> 项 | G14: 1 | H14: =VLOOKUP(D14,[31]材料表!$B$4:$G$80,4,0) -> 5 | I14: =G14*H14 -> 5
D28: 合计 | I28: =SUM(I4:I27) -> 426.57911
C29: 人工费 | F29: 元 | I29: 70
C30: 机械费 | F30: 元 | I30: 5
B31: 本项小计 | F31: 元 | I31: =SUM(I28:I30) -> 501.57911
A32: 二 | B32: 管理费 | E32: （一）* 4% | F32: 元 | I32: =I31*$K$2 -> 0
A33: 三 | B33: 利润 | E33: （一+二）* 5% | F33: 元 | I33: =(I32+I31)*5% -> 25.078955
A34: 四 | B34: 税金 | E34: （一+二+三）* 3.43% | F34: 元 | I34: =SUM(I31:I33)*$M$2 -> 0
A35: 五 | B35: 单位造价合计 | E35: （一+二+三+四） | F35: 元 | I35: =SUM(I31:I34) -> 526.65806

Sheet MS65F

Sheet WM1127
B2: MS65F系列（注胶角码） | D2: 24mm | E2: 表面处理 | F2: 静电粉末喷涂 | I2: N0.1 | J2: 副框线重速求表
B3: 代号 | C3: 门窗尺寸 | D3: 宽度 | E3: 高度 | F3: 面积 | G3: 樘数 | H3: 总面积 | J3: 宽度:mm | K3: 高度:mm | L3: 壁厚:mm | M3: 线重
B4: =MID(CELL("filename",Q13),FIND("]",CELL("filename",Q13))+1,30) -> WM1127 | C4: 洞口尺寸 | D4: 1100 | E4: 2650 | F4: 2.785 | G4: 1 | H4: =F4*G4 -> 2.785 | J4: 40 | K4: 20 | L4: 1.5 | M4: =ROUND(((J4*K4)-(J4-2*L4)*(K4-2*L4))*7.8/1000,3) -> 1.334
C5: 附框内口尺寸 | D5: =D4-70 -> 1030 | E5: =E4-70 -> 2580 | F5: =D5*E5/10^6 -> 2.6574 | G5: 1 | H5: =F5*G5 -> 2.6574 | J5: 40 | K5: 20 | L5: 2 | M5: =ROUND(((J5*K5)-(J5-2*L5)*(K5-2*L5))*7.8/1000,3) -> 1.747
C6: 主框尺寸 | D6: =D4-80 -> 1020 | E6: =E4-80 -> 2570 | F6: =D6*E6/10^6 -> 2.6214 | G6: 1 | H6: =F6*G6 -> 2.6214 | J6: 40 | K6: 20 | L6: 2 | M6: =ROUND(((J6*K6)-(J6-2*L6)*(K6-2*L6))*7.8/1000,3) -> 1.747
B7: 钢副框（热） | C7: 宽度 | D7: 宽数量 | E7: 高度 | F7: 高数量 | G7: 线重 | H7: 单价 | I7: 总价 | J7: 80 | K7: 40 | L7: 2 | M7: =ROUND(((J7*K7)-(J7-2*L7)*(K7-2*L7))*7.8/1000,3) -> 3.619
B8: 40*20*2.0 | C8: =D4-30 -> 1070 | D8: 2 | E8: =E4-30 -> 2620 | F8: 2 | G8: 1.747 | H8: =材料价格!B3 -> 7.5 | I8: =ROUND((C8*D8+E8*F8)*G8*H8/1000*1.1,2) -> 106.37 | J8: 40 | K8: 20 | L8: 1.4 | M8: =ROUND(((J8*K8)-(J8-2*L8)*(K8-2*L8))*2.71/1000,3) -> 0.434
B9: 40*20*2.0 | G9: 1.747 | H9: =H8 -> 7.5 | I9: =ROUND((C9*D9+E9*F9)*G9*H9/1000*1.1,2) -> 0 | M9: =ROUND(((J9*K9)-(J9-2*L9)*(K9-2*L9))*7.8/1000,3) -> 0
B10: 80*40*2 | G10: 3.619 | H10: =H9 -> 7.5 | I10: =ROUND((C10*D10+E10*F10)*G10*H10/1000*1.1,2) -> 0 | M10: =ROUND(((J10*K10)-(J10-2*L10)*(K10-2*L10))*7.8/1000,3) -> 0
B11: 50*50*2.0 | G11: 2.995 | H11: =H10 -> 7.5 | I11: =ROUND((C11*D11+E11*F11)*G11*H11/1000*1.1,2) -> 0 | M11: =ROUND(((J11*K11)-(J11-2*L11)*(K11-2*L11))*7.8/1000,3) -> 0
B12: 副框平米用量 | C12: =((I9+I10+I8+I11)/H8)/F4 -> 5.0925194 | D12: （Kg/m2) | E12: =(I9+I10+I8+I11)/F4 -> 38.193896 | F12: （元/m2) | H12: =ROUND(SUM(I8:I11)/H8,2) -> 14.18 | I12: =SUM(I8:I11) -> 106.37
B13: 型材名称 | C13: 代号 | D13: 横 | E13: 竖 | F13: 周长 | G13: 数量 | H13: 线重 | I13: 重量
B14: 平开窗框 | C14: SDF2894 | D14: =D6 -> 1020 | E14: =E6-E108 -> 520 | F14: =ROUND((D14+E14)*2/1000,4) -> 3.08 | G14: 1 | H14: 1.47 | I14: =ROUND(F14*G14*H14,3)*1.5 -> 6.792
F15: =ROUND((D15+E15)*2/1000,4) -> 0 | H15: =H14 -> 1.47 | I15: =ROUND(F15*G15*H15,3) -> 0
F16: =ROUND((D16+E16)*2/1000,4) -> 0 | H16: =H15 -> 1.47 | I16: =ROUND(F16*G16*H16,3) -> 0
F17: =ROUND((D17+E17)*2/1000,4) -> 0 | H17: =H16 -> 1.47 | I17: =ROUND(F17*G17*H17,3) -> 0
F18: =ROUND((D18+E18)*2/1000,4) -> 0 | H18: =H17 -> 1.47 | I18: =ROUND(F18*G18*H18,3) -> 0
F19: =ROUND((D19+E19)*2/1000,4) -> 0 | H19: =H18 -> 1.47 | I19: =ROUND(F19*G19*H19,3) -> 0
F20: =ROUND((D20+E20)*2/1000,4) -> 0 | H20: =H19 -> 1.47 | I20: =ROUND(F20*G20*H20,3) -> 0
F21: =ROUND((D21+E21)*2/1000,4) -> 0 | H21: =H20 -> 1.47 | I21: =ROUND(F21*G21*H21,3) -> 0
B22: 型材总长度 | C22: =SUMPRODUCT(F14:F21*G14:G21) -> 3.08 | D22: 型材总重量 | E22: =SUM(I14:I21)*1.1 -> 7.4712 | F22: 型材单价 | G22: =(C$218+C$219)/1000 -> 46.0815 | H22: 型材总价 | I22: =ROUND(E22*G22,2) -> 344.28 | J22: =SUM(G14:G21) -> 1
B23: 外侧装饰面长 | C23: 207.36 | D23: 外侧装饰面积 | E23: =ROUND(C22*(C23/1000),2) -> 0.64 | F23: 喷涂单价 | G23: 10 | H23: 喷涂总价 | I23: =E23*G23 -> 6.4
B24: 内侧装饰面长 | C24: 169.96 | D24: 内侧装饰面积 | E24: =ROUND(C22*(C24/1000),2) -> 0.52 | F24: 喷涂单价 | G24: 10 | H24: 喷涂总价 | I24: =E24*G24 -> 5.2
B25: 型材名称 | C25: 代号 | D25: 横 | E25: 竖 | F25: 周长 | G25: 数量 | H25: 线重 | I25: 重量 | J25: 宽 | K25: 高 | L25: 宽缩尺 | M25: 高缩尺 | N25: 代号
B26: 内平开窗扇 | C26: SDF2885 | D26: =J26-IF(L26=1,44,IF(L26=2,30,IF(L26=3,16,0))) -> 0 | E26: =K26-IF(M26=1,44,IF(M26=2,30,IF(M26=3,16,0))) -> 0 | F26: =ROUND((D26+E26)*2/1000,4) -> 0 | H26: 1.62 | I26: =IF(AND(D26>0,E26>0,F26>0),F26*G26*H26,0) -> 0 | N26: 1.框-框 | O26: 普通扇
D27: =J27-IF(L27=1,44,IF(L27=2,30,IF(L27=3,16,0))) -> 0 | E27: =K27-IF(M27=1,44,IF(M27=2,30,IF(M27=3,16,0))) -> 0 | F27: =ROUND((D27+E27)*2/1000,4) -> 0 | H27: =H26 -> 1.62 | I27: =IF(AND(D27>0,E27>0,F27>0),F27*G27*H27,0) -> 0 | N27: 2.框-中梃 | O27: 钢化扇
D28: =J28-IF(L28=1,44,IF(L28=2,30,IF(L28=3,16,0))) -> 0 | E28: =K28-IF(M28=1,44,IF(M28=2,30,IF(M28=3,16,0))) -> 0 | F28: =ROUND((D28+E28)*2/1000,4) -> 0 | H28: =H27 -> 1.62 | I28: =IF(AND(D28>0,E28>0,F28>0),F28*G28*H28,0) -> 0 | N28: 3.中梃-中梃 | O28: 钢化扇
D29: =J29-IF(L29=1,44,IF(L29=2,30,IF(L29=3,16,0))) -> 0 | E29: =K29-IF(M29=1,44,IF(M29=2,30,IF(M29=3,16,0))) -> 0 | F29: =ROUND((D29+E29)*2/1000,4) -> 0 | H29: =H28 -> 1.62 | I29: =IF(AND(D29>0,E29>0,F29>0),F29*G29*H29,0) -> 0
D30: =J30-IF(L30=1,44,IF(L30=2,30,IF(L30=3,16,0))) -> 0 | E30: =K30-IF(M30=1,44,IF(M30=2,30,IF(M30=3,16,0))) -> 0 | F30: =ROUND((D30+E30)*2/1000,4) -> 0 | H30: =H29 -> 1.62 | I30: =IF(AND(D30>0,E30>0,F30>0),F30*G30*H30,0) -> 0
B31: 型材总长度 | C31: =SUMPRODUCT(F26:F30*G26:G30) -> 0 | D31: 型材总重量 | E31: =SUM(I26:I30)*1.1 -> 0 | F31: 型材单价 | G31: =(C$218+C$221)/1000 -> 46.0815 | H31: 型材总价 | I31: =ROUND(E31*G31,2) -> 0 | J31: =SUM(G26:G30) -> 0
B32: 外侧装饰面长 | C32: 183.32 | D32: 外侧装饰面积 | E32: =ROUND(C31*(C32/1000),2) -> 0 | F32: 喷涂单价 | G32: =G$23 -> 10 | H32: 喷涂总价 | I32: =E32*G32 -> 0
B33: 内侧装饰面长 | C33: 257.82 | D33: 内侧装饰面积 | E33: =ROUND(C31*(C33/1000),2) -> 0 | F33: 喷涂单价 | G33: =G$24 -> 10 | H33: 喷涂总价 | I33: =E33*G33 -> 0
B34: 型材名称 | C34: 代号 | D34: 横 | E34: 竖 | F34: 周长 | G34: 数量 | H34: 线重 | I34: 重量 | J34: 宽 | K34: 高 | L34: （宽）缩尺 | M34: （高）缩尺 | N34: 代号
B35: 外平开窗扇 | C35: SDF2806 | D35: =J35-IF(L35=1,44,IF(L35=2,30,IF(L35=3,16,IF(L35=11,118,IF(L35=12,100,IF(L35=13,76.8,0)))))) -> 0 | E35: =K35-IF(M35=1,44,IF(M35=2,30,IF(M35=3,16,IF(M35=11,118,IF(M35=12,100,IF(M35=13,76.8,0)))))) -> 0 | F35: =ROUND((D35+E35)*2/1000,4) -> 0 | H35: 1.814 | I35: =ROUND(F35*G35*H35,3) -> 0 | N35: 1.框-框
D36: =J36-IF(L36=1,44,IF(L36=2,30,IF(L36=3,16,IF(L36=11,118,IF(L36=12,100,IF(L36=13,76.8,0)))))) -> 0 | E36: =K36-IF(M36=1,44,IF(M36=2,30,IF(M36=3,16,IF(M36=11,118,IF(M36=12,100,IF(M36=13,76.8,0)))))) -> 0 | F36: =ROUND((D36+E36)*2/1000,4) -> 0 | H36: =H35 -> 1.814 | I36: =ROUND(F36*G36*H36,3) -> 0 | N36: 2.框-中梃
D37: =J37-IF(L37=1,44,IF(L37=2,30,IF(L37=3,16,IF(L37=11,118,IF(L37=12,100,IF(L37=13,76.8,0)))))) -> 0 | E37: =K37-IF(M37=1,44,IF(M37=2,30,IF(M37=3,16,IF(M37=11,118,IF(M37=12,100,IF(M37=13,76.8,0)))))) -> 0 | F37: =ROUND((D37+E37)*2/1000,4) -> 0 | H37: =H36 -> 1.814 | I37: =ROUND(F37*G37*H37,3) -> 0 | N37: 3.中梃-中梃
B38: 型材总长度 | C38: =SUMPRODUCT(F35:F37*G35:G37) -> 0 | D38: 型材总重量 | E38: =SUM(I35:I37)*1.1 -> 0 | F38: 型材单价 | G38: =(C$218+C$219)/1000 -> 46.0815 | H38: 型材总价 | I38: =ROUND(E38*G38,2) -> 0 | J38: =SUM(G35:G37) -> 0 | N38: 11.转.框-框
B39: 外侧装饰面长 | C39: 320.14 | D39: 外侧装饰面积 | E39: =ROUND(C38*(C39/1000),2) -> 0 | F39: 喷涂单价 | G39: =G$23 -> 10 | H39: 喷涂总价 | I39: =E39*G39 -> 0 | N39: 12.转.框-中梃
B40: 内侧装饰面长 | C40: 156.99 | D40: 内侧装饰面积 | E40: =ROUND(C38*(C40/1000),2) -> 0 | F40: 喷涂单价 | G40: =G$24 -> 10 | H40: 喷涂总价 | I40: =E40*G40 -> 0 | N40: 13.转.中梃-中梃
B41: 型材名称 | C41: 代号 | D41: 横 | E41: 竖 | F41: 周长 | G41: 数量 | H41: 线重 | I41: 重量 | J41: 宽 | K41: 高 | L41: （宽）缩尺 | M41: （高）缩尺 | N41: 代号
...

Sheet C1014
B2: MS65F系列（注胶角码） | D2: 24mm | E2: 表面处理 | F2: 静电粉末喷涂 | I2: N0.1 | J2: 副框线重速求表
B3: 代号 | C3: 门窗尺寸 | D3: 宽度 | E3: 高度 | F3: 面积 | G3: 樘数 | H3: 总面积 | J3: 宽度:mm | K3: 高度:mm | L3: 壁厚:mm | M3: 线重
B4: =MID(CELL("filename",Q13),FIND("]",CELL("filename",Q13))+1,30) -> C1014 | C4: 洞口尺寸 | D4: 1000 | E4: 1400 | F4: 1.1 | G4: 1 | H4: =F4*G4 -> 1.1 | J4: 40 | K4: 20 | L4: 1.5 | M4: =ROUND(((J4*K4)-(J4-2*L4)*(K4-2*L4))*7.8/1000,3) -> 1.334
C5: 附框内口尺寸 | D5: =D4-70 -> 930 | E5: =E4-70 -> 1330 | F5: =D5*E5/10^6 -> 1.2369 | G5: 1 | H5: =F5*G5 -> 1.2369 | J5: 40 | K5: 20 | L5: 2 | M5: =ROUND(((J5*K5)-(J5-2*L5)*(K5-2*L5))*7.8/1000,3) -> 1.747
C6: 主框尺寸 | D6: =D4-80 -> 920 | E6: =E4-80 -> 1320 | F6: =D6*E6/10^6 -> 1.2144 | G6: 1 | H6: =F6*G6 -> 1.2144 | J6: 40 | K6: 20 | L6: 2 | M6: =ROUND(((J6*K6)-(J6-2*L6)*(K6-2*L6))*7.8/1000,3) -> 1.747
B7: 钢副框（热） | C7: 宽度 | D7: 宽数量 | E7: 高度 | F7: 高数量 | G7: 线重 | H7: 单价 | I7: 总价 | J7: 80 | K7: 40 | L7: 2 | M7: =ROUND(((J7*K7)-(J7-2*L7)*(K7-2*L7))*7.8/1000,3) -> 3.619
B8: 40*20*2.0 | C8: =D4-30 -> 970 | D8: 2 | E8: =E4-30 -> 1370 | F8: 2 | G8: 1.747 | H8: =材料价格!B3 -> 7.5 | I8: =ROUND((C8*D8+E8*F8)*G8*H8/1000*1.1,2) -> 67.45 | J8: 40 | K8: 20 | L8: 1.4 | M8: =ROUND(((J8*K8)-(J8-2*L8)*(K8-2*L8))*2.71/1000,3) -> 0.434
B9: 40*20*2.0 | G9: 1.747 | H9: =H8 -> 7.5 | I9: =ROUND((C9*D9+E9*F9)*G9*H9/1000*1.1,2) -> 0 | M9: =ROUND(((J9*K9)-(J9-2*L9)*(K9-2*L9))*7.8/1000,3) -> 0
B10: 80*40*2 | G10: 3.619 | H10: =H9 -> 7.5 | I10: =ROUND((C10*D10+E10*F10)*G10*H10/1000*1.1,2) -> 0 | M10: =ROUND(((J10*K10)-(J10-2*L10)*(K10-2*L10))*7.8/1000,3) -> 0
B11: 50*50*2.0 | G11: 2.995 | H11: =H10 -> 7.5 | I11: =ROUND((C11*D11+E11*F11)*G11*H11/1000*1.1,2) -> 0 | M11: =ROUND(((J11*K11)-(J11-2*L11)*(K11-2*L11))*7.8/1000,3) -> 0
B12: 副框平米用量 | C12: =((I9+I10+I8+I11)/H8)/F4 -> 8.1757576 | D12: （Kg/m2) | E12: =(I9+I10+I8+I11)/F4 -> 61.318182 | F12: （元/m2) | H12: =ROUND(SUM(I8:I11)/H8,2) -> 8.99 | I12: =SUM(I8:I11) -> 67.45
B13: 型材名称 | C13: 代号 | D13: 横 | E13: 竖 | F13: 周长 | G13: 数量 | H13: 线重 | I13: 重量
B14: 平开窗框 | C14: SDF2894 | D14: =D6 -> 920 | E14: =E6 -> 1320 | F14: =ROUND((D14+E14)*2/1000,4) -> 4.48 | G14: 1 | H14: 1.47 | I14: =ROUND(F14*G14*H14,3)*3 -> 19.758
F15: =ROUND((D15+E15)*2/1000,4) -> 0 | H15: =H14 -> 1.47 | I15: =ROUND(F15*G15*H15,3) -> 0
F16: =ROUND((D16+E16)*2/1000,4) -> 0 | H16: =H15 -> 1.47 | I16: =ROUND(F16*G16*H16,3) -> 0
F17: =ROUND((D17+E17)*2/1000,4) -> 0 | H17: =H16 -> 1.47 | I17: =ROUND(F17*G17*H17,3) -> 0
F18: =ROUND((D18+E18)*2/1000,4) -> 0 | H18: =H17 -> 1.47 | I18: =ROUND(F18*G18*H18,3) -> 0
F19: =ROUND((D19+E19)*2/1000,4) -> 0 | H19: =H18 -> 1.47 | I19: =ROUND(F19*G19*H19,3) -> 0
F20: =ROUND((D20+E20)*2/1000,4) -> 0 | H20: =H19 -> 1.47 | I20: =ROUND(F20*G20*H20,3) -> 0
F21: =ROUND((D21+E21)*2/1000,4) -> 0 | H21: =H20 -> 1.47 | I21: =ROUND(F21*G21*H21,3) -> 0
B22: 型材总长度 | C22: =SUMPRODUCT(F14:F21*G14:G21) -> 4.48 | D22: 型材总重量 | E22: =SUM(I14:I21)*1.1 -> 21.7338 | F22: 型材单价 | G22: =(C$218+C$219)/1000 -> 46.0815 | H22: 型材总价 | I22: =ROUND(E22*G22,2) -> 1001.53 | J22: =SUM(G14:G21) -> 1
B23: 外侧装饰面长 | C23: 207.36 | D23: 外侧装饰面积 | E23: =ROUND(C22*(C23/1000),2) -> 0.93 | F23: 喷涂单价 | G23: 10 | H23: 喷涂总价 | I23: =E23*G23 -> 9.3
B24: 内侧装饰面长 | C24: 169.96 | D24: 内侧装饰面积 | E24: =ROUND(C22*(C24/1000),2) -> 0.76 | F24: 喷涂单价 | G24: 10 | H24: 喷涂总价 | I24: =E24*G24 -> 7.6
B25: 型材名称 | C25: 代号 | D25: 横 | E25: 竖 | F25: 周长 | G25: 数量 | H25: 线重 | I25: 重量 | J25: 宽 | K25: 高 | L25: 宽缩尺 | M25: 高缩尺 | N25: 代号
B26: 内平开窗扇 | C26: SDF2885 | D26: =J26-IF(L26=1,44,IF(L26=2,30,IF(L26=3,16,0))) -> 0 | E26: =K26-IF(M26=1,44,IF(M26=2,30,IF(M26=3,16,0))) -> 0 | F26: =ROUND((D26+E26)*2/1000,4) -> 0 | H26: 1.62 | I26: =IF(AND(D26>0,E26>0,F26>0),F26*G26*H26,0) -> 0 | N26: 1.框-框 | O26: 普通扇
D27: =J27-IF(L27=1,44,IF(L27=2,30,IF(L27=3,16,0))) -> 0 | E27: =K27-IF(M27=1,44,IF(M27=2,30,IF(M27=3,16,0))) -> 0 | F27: =ROUND((D27+E27)*2/1000,4) -> 0 | H27: =H26 -> 1.62 | I27: =IF(AND(D27>0,E27>0,F27>0),F27*G27*H27,0) -> 0 | N27: 2.框-中梃 | O27: 钢化扇
D28: =J28-IF(L28=1,44,IF(L28=2,30,IF(L28=3,16,0))) -> 0 | E28: =K28-IF(M28=1,44,IF(M28=2,30,IF(M28=3,16,0))) -> 0 | F28: =ROUND((D28+E28)*2/1000,4) -> 0 | H28: =H27 -> 1.62 | I28: =IF(AND(D28>0,E28>0,F28>0),F28*G28*H28,0) -> 0 | N28: 3.中梃-中梃 | O28: 钢化扇
D29: =J29-IF(L29=1,44,IF(L29=2,30,IF(L29=3,16,0))) -> 0 | E29: =K29-IF(M29=1,44,IF(M29=2,30,IF(M29=3,16,0))) -> 0 | F29: =ROUND((D29+E29)*2/1000,4) -> 0 | H29: =H28 -> 1.62 | I29: =IF(AND(D29>0,E29>0,F29>0),F29*G29*H29,0) -> 0
D30: =J30-IF(L30=1,44,IF(L30=2,30,IF(L30=3,16,0))) -> 0 | E30: =K30-IF(M30=1,44,IF(M30=2,30,IF(M30=3,16,0))) -> 0 | F30: =ROUND((D30+E30)*2/1000,4) -> 0 | H30: =H29 -> 1.62 | I30: =IF(AND(D30>0,E30>0,F30>0),F30*G30*H30,0) -> 0
B31: 型材总长度 | C31: =SUMPRODUCT(F26:F30*G26:G30) -> 0 | D31: 型材总重量 | E31: =SUM(I26:I30)*1.1 -> 0 | F31: 型材单价 | G31: =(C$218+C$221)/1000 -> 46.0815 | H31: 型材总价 | I31: =ROUND(E31*G31,2) -> 0 | J31: =SUM(G26:G30) -> 0
B32: 外侧装饰面长 | C32: 183.32 | D32: 外侧装饰面积 | E32: =ROUND(C31*(C32/1000),2) -> 0 | F32: 喷涂单价 | G32: =G$23 -> 10 | H32: 喷涂总价 | I32: =E32*G32 -> 0
B33: 内侧装饰面长 | C33: 257.82 | D33: 内侧装饰面积 | E33: =ROUND(C31*(C33/1000),2) -> 0 | F33: 喷涂单价 | G33: =G$24 -> 10 | H33: 喷涂总价 | I33: =E33*G33 -> 0
B34: 型材名称 | C34: 代号 | D34: 横 | E34: 竖 | F34: 周长 | G34: 数量 | H34: 线重 | I34: 重量 | J34: 宽 | K34: 高 | L34: （宽）缩尺 | M34: （高）缩尺 | N34: 代号
B35: 外平开窗扇 | C35: SDF2806 | D35: =J35-IF(L35=1,44,IF(L35=2,30,IF(L35=3,16,IF(L35=11,118,IF(L35=12,100,IF(L35=13,76.8,0)))))) -> 0 | E35: =K35-IF(M35=1,44,IF(M35=2,30,IF(M35=3,16,IF(M35=11,118,IF(M35=12,100,IF(M35=13,76.8,0)))))) -> 0 | F35: =ROUND((D35+E35)*2/1000,4) -> 0 | H35: 1.814 | I35: =ROUND(F35*G35*H35,3) -> 0 | N35: 1.框-框
D36: =J36-IF(L36=1,44,IF(L36=2,30,IF(L36=3,16,IF(L36=11,118,IF(L36=12,100,IF(L36=13,76.8,0)))))) -> 0 | E36: =K36-IF(M36=1,44,IF(M36=2,30,IF(M36=3,16,IF(M36=11,118,IF(M36=12,100,IF(M36=13,76.8,0)))))) -> 0 | F36: =ROUND((D36+E36)*2/1000,4) -> 0 | H36: =H35 -> 1.814 | I36: =ROUND(F36*G36*H36,3) -> 0 | N36: 2.框-中梃
D37: =J37-IF(L37=1,44,IF(L37=2,30,IF(L37=3,16,IF(L37=11,118,IF(L37=12,100,IF(L37=13,76.8,0)))))) -> 0 | E37: =K37-IF(M37=1,44,IF(M37=2,30,IF(M37=3,16,IF(M37=11,118,IF(M37=12,100,IF(M37=13,76.8,0)))))) -> 0 | F37: =ROUND((D37+E37)*2/1000,4) -> 0 | H37: =H36 -> 1.814 | I37: =ROUND(F37*G37*H37,3) -> 0 | N37: 3.中梃-中梃
B38: 型材总长度 | C38: =SUMPRODUCT(F35:F37*G35:G37) -> 0 | D38: 型材总重量 | E38: =SUM(I35:I37)*1.1 -> 0 | F38: 型材单价 | G38: =(C$218+C$219)/1000 -> 46.0815 | H38: 型材总价 | I38: =ROUND(E38*G38,2) -> 0 | J38: =SUM(G35:G37) -> 0 | N38: 11.转.框-框
B39: 外侧装饰面长 | C39: 320.14 | D39: 外侧装饰面积 | E39: =ROUND(C38*(C39/1000),2) -> 0 | F39: 喷涂单价 | G39: =G$23 -> 10 | H39: 喷涂总价 | I39: =E39*G39 -> 0 | N39: 12.转.框-中梃
B40: 内侧装饰面长 | C40: 156.99 | D40: 内侧装饰面积 | E40: =ROUND(C38*(C40/1000),2) -> 0 | F40: 喷涂单价 | G40: =G$24 -> 10 | H40: 喷涂总价 | I40: =E40*G40 -> 0 | N40: 13.转.中梃-中梃
B41: 型材名称 | C41: 代号 | D41: 横 | E41: 竖 | F41: 周长 | G41: 数量 | H41: 线重 | I41: 重量 | J41: 宽 | K41: 高 | L41: （宽）缩尺 | M41: （高）缩尺 | N41: 代号
...

Sheet C1117
B2: MS65F系列（注胶角码） | D2: 24mm | E2: 表面处理 | F2: 静电粉末喷涂 | I2: N0.1 | J2: 副框线重速求表
B3: 代号 | C3: 门窗尺寸 | D3: 宽度 | E3: 高度 | F3: 面积 | G3: 樘数 | H3: 总面积 | J3: 宽度:mm | K3: 高度:mm | L3: 壁厚:mm | M3: 线重
B4: =MID(CELL("filename",Q13),FIND("]",CELL("filename",Q13))+1,30) -> C1117 | C4: 洞口尺寸 | D4: 1100 | E4: 1700 | F4: 1.74 | G4: 1 | H4: =F4*G4 -> 1.74 | J4: 40 | K4: 20 | L4: 1.5 | M4: =ROUND(((J4*K4)-(J4-2*L4)*(K4-2*L4))*7.8/1000,3) -> 1.334
C5: 附框内口尺寸 | D5: =D4-70 -> 1030 | E5: =E4-70 -> 1630 | F5: =D5*E5/10^6 -> 1.6789 | G5: 1 | H5: =F5*G5 -> 1.6789 | J5: 40 | K5: 20 | L5: 2 | M5: =ROUND(((J5*K5)-(J5-2*L5)*(K5-2*L5))*7.8/1000,3) -> 1.747
C6: 主框尺寸 | D6: =D4-80 -> 1020 | E6: =E4-80 -> 1620 | F6: =D6*E6/10^6 -> 1.6524 | G6: 1 | H6: =F6*G6 -> 1.6524 | J6: 40 | K6: 20 | L6: 2 | M6: =ROUND(((J6*K6)-(J6-2*L6)*(K6-2*L6))*7.8/1000,3) -> 1.747
